Workbook

Sheet Summary
A1: TC_LuatLD — Test Summary
A2: Effective Status = Final Status (tester) nếu đã điền, nếu không = Suggested Status (tự động).
A4: Status | B4: Count | C4: Rate
A5: PASS | B5: =COUNTIF(Results!$AA$2:$AA$101,"PASS") | C5: =B5/100
A6: PARTIAL | B6: =COUNTIF(Results!$AA$2:$AA$101,"PARTIAL") | C6: =B6/100
A7: FAIL | B7: =COUNTIF(Results!$AA$2:$AA$101,"FAIL") | C7: =B7/100
A8: BLOCKED | B8: =COUNTIF(Results!$AA$2:$AA$101,"BLOCKED") | C8: =B8/100
A9: Total | B9: =SUM(B5:B8)
A10: Reviewed by tester | B10: =COUNTA(Results!Z2:Z101)
A11: Median latency (s) | B11: 20.5
A13: Theo tài liệu
A14: Document | B14: Total | C14: PASS | D14: PARTIAL | E14: FAIL | F14: BLOCKED | G14: Pass rate
A15: giao trinh Luat lao dong CB 2005 (1) | B15: =COUNTIF(Results!$N$2:$N$101,A15) | C15: =COUNTIFS(Results!$N$2:$N$101,A15,Results!$AA$2:$AA$101,"PASS") | D15: =COUNTIFS(Results!$N$2:$N$101,A15,Results!$AA$2:$AA$101,"PARTIAL") | E15: =COUNTIFS(Results!$N$2:$N$101,A15,Results!$AA$2:$AA$101,"FAIL") | F15: =COUNTIFS(Results!$N$2:$N$101,A15,Results!$AA$2:$AA$101,"BLOCKED") | G15: =IF(B15=0,0,C15/B15)
A16: so-tay-kien-thuc-phap-luat-lao-dong-cdi | B16: =COUNTIF(Results!$N$2:$N$101,A16) | C16: =COUNTIFS(Results!$N$2:$N$101,A16,Results!$AA$2:$AA$101,"PASS") | D16: =COUNTIFS(Results!$N$2:$N$101,A16,Results!$AA$2:$AA$101,"PARTIAL") | E16: =COUNTIFS(Results!$N$2:$N$101,A16,Results!$AA$2:$AA$101,"FAIL") | F16: =COUNTIFS(Results!$N$2:$N$101,A16,Results!$AA$2:$AA$101,"BLOCKED") | G16: =IF(B16=0,0,C16/B16)
A17: luu-ban-nhap-tu-dong-3-4 | B17: =COUNTIF(Results!$N$2:$N$101,A17) | C17: =COUNTIFS(Results!$N$2:$N$101,A17,Results!$AA$2:$AA$101,"PASS") | D17: =COUNTIFS(Results!$N$2:$N$101,A17,Results!$AA$2:$AA$101,"PARTIAL") | E17: =COUNTIFS(Results!$N$2:$N$101,A17,Results!$AA$2:$AA$101,"FAIL") | F17: =COUNTIFS(Results!$N$2:$N$101,A17,Results!$AA$2:$AA$101,"BLOCKED") | G17: =IF(B17=0,0,C17/B17)
A18: ILO-VCCI_Labour-Law-Guide-Book-V04-Final | B18: =COUNTIF(Results!$N$2:$N$101,A18) | C18: =COUNTIFS(Results!$N$2:$N$101,A18,Results!$AA$2:$AA$101,"PASS") | D18: =COUNTIFS(Results!$N$2:$N$101,A18,Results!$AA$2:$AA$101,"PARTIAL") | E18: =COUNTIFS(Results!$N$2:$N$101,A18,Results!$AA$2:$AA$101,"FAIL") | F18: =COUNTIFS(Results!$N$2:$N$101,A18,Results!$AA$2:$AA$101,"BLOCKED") | G18: =IF(B18=0,0,C18/B18)
A19: Văn-bản-hợp-nhất-18-VBHN-VPQH | B19: =COUNTIF(Results!$N$2:$N$101,A19) | C19: =COUNTIFS(Results!$N$2:$N$101,A19,Results!$AA$2:$AA$101,"PASS") | D19: =COUNTIFS(Results!$N$2:$N$101,A19,Results!$AA$2:$AA$101,"PARTIAL") | E19: =COUNTIFS(Results!$N$2:$N$101,A19,Results!$AA$2:$AA$101,"FAIL") | F19: =COUNTIFS(Results!$N$2:$N$101,A19,Results!$AA$2:$AA$101,"BLOCKED") | G19: =IF(B19=0,0,C19/B19)
A21: Theo độ khó
A22: Retrieval Difficulty | B22: Total | C22: PASS | D22: PARTIAL | E22: FAIL | F22: BLOCKED | G22: Pass rate
A23: Easy | B23: =COUNTIF(Results!$I$2:$I$101,A23) | C23: =COUNTIFS(Results!$I$2:$I$101,A23,Results!$AA$2:$AA$101,"PASS") | D23: =COUNTIFS(Results!$I$2:$I$101,A23,Results!$AA$2:$AA$101,"PARTIAL") | E23: =COUNTIFS(Results!$I$2:$I$101,A23,Results!$AA$2:$AA$101,"FAIL") | F23: =COUNTIFS(Results!$I$2:$I$101,A23,Results!$AA$2:$AA$101,"BLOCKED") | G23: =IF(B23=0,0,C23/B23)
A24: Medium | B24: =COUNTIF(Results!$I$2:$I$101,A24) | C24: =COUNTIFS(Results!$I$2:$I$101,A24,Results!$AA$2:$AA$101,"PASS") | D24: =COUNTIFS(Results!$I$2:$I$101,A24,Results!$AA$2:$AA$101,"PARTIAL") | E24: =COUNTIFS(Results!$I$2:$I$101,A24,Results!$AA$2:$AA$101,"FAIL") | F24: =COUNTIFS(Results!$I$2:$I$101,A24,Results!$AA$2:$AA$101,"BLOCKED") | G24: =IF(B24=0,0,C24/B24)
A25: Hard | B25: =COUNTIF(Results!$I$2:$I$101,A25) | C25: =COUNTIFS(Results!$I$2:$I$101,A25,Results!$AA$2:$AA$101,"PASS") | D25: =COUNTIFS(Results!$I$2:$I$101,A25,Results!$AA$2:$AA$101,"PARTIAL") | E25: =COUNTIFS(Results!$I$2:$I$101,A25,Results!$AA$2:$AA$101,"FAIL") | F25: =COUNTIFS(Results!$I$2:$I$101,A25,Results!$AA$2:$AA$101,"BLOCKED") | G25: =IF(B25=0,0,C25/B25)
A27: Theo loại câu hỏi
A28: Category | B28: Total | C28: PASS | D28: PARTIAL | E28: FAIL | F28: BLOCKED | G28: Pass rate
A29: Definition | B29: =COUNTIF(Results!$B$2:$B$101,A29) | C29: =COUNTIFS(Results!$B$2:$B$101,A29,Results!$AA$2:$AA$101,"PASS") | D29: =COUNTIFS(Results!$B$2:$B$101,A29,Results!$AA$2:$AA$101,"PARTIAL") | E29: =COUNTIFS(Results!$B$2:$B$101,A29,Results!$AA$2:$AA$101,"FAIL") | F29: =COUNTIFS(Results!$B$2:$B$101,A29,Results!$AA$2:$AA$101,"BLOCKED") | G29: =IF(B29=0,0,C29/B29)
A30: List | B30: =COUNTIF(Results!$B$2:$B$101,A30) | C30: =COUNTIFS(Results!$B$2:$B$101,A30,Results!$AA$2:$AA$101,"PASS") | D30: =COUNTIFS(Results!$B$2:$B$101,A30,Results!$AA$2:$AA$101,"PARTIAL") | E30: =COUNTIFS(Results!$B$2:$B$101,A30,Results!$AA$2:$AA$101,"FAIL") | F30: =COUNTIFS(Results!$B$2:$B$101,A30,Results!$AA$2:$AA$101,"BLOCKED") | G30: =IF(B30=0,0,C30/B30)
A31: Direct Fact | B31: =COUNTIF(Results!$B$2:$B$101,A31) | C31: =COUNTIFS(Results!$B$2:$B$101,A31,Results!$AA$2:$AA$101,"PASS") | D31: =COUNTIFS(Results!$B$2:$B$101,A31,Results!$AA$2:$AA$101,"PARTIAL") | E31: =COUNTIFS(Results!$B$2:$B$101,A31,Results!$AA$2:$AA$101,"FAIL") | F31: =COUNTIFS(Results!$B$2:$B$101,A31,Results!$AA$2:$AA$101,"BLOCKED") | G31: =IF(B31=0,0,C31/B31)
A32: Concept | B32: =COUNTIF(Results!$B$2:$B$101,A32) | C32: =COUNTIFS(Results!$B$2:$B$101,A32,Results!$AA$2:$AA$101,"PASS") | D32: =COUNTIFS(Results!$B$2:$B$101,A32,Results!$AA$2:$AA$101,"PARTIAL") | E32: =COUNTIFS(Results!$B$2:$B$101,A32,Results!$AA$2:$AA$101,"FAIL") | F32: =COUNTIFS(Results!$B$2:$B$101,A32,Results!$AA$2:$AA$101,"BLOCKED") | G32: =IF(B32=0,0,C32/B32)
A33: Rule | B33: =COUNTIF(Results!$B$2:$B$101,A33) | C33: =COUNTIFS(Results!$B$2:$B$101,A33,Results!$AA$2:$AA$101,"PASS") | D33: =COUNTIFS(Results!$B$2:$B$101,A33,Results!$AA$2:$AA$101,"PARTIAL") | E33: =COUNTIFS(Results!$B$2:$B$101,A33,Results!$AA$2:$AA$101,"FAIL") | F33: =COUNTIFS(Results!$B$2:$B$101,A33,Results!$AA$2:$AA$101,"BLOCKED") | G33: =IF(B33=0,0,C33/B33)
A34: Comparison | B34: =COUNTIF(Results!$B$2:$B$101,A34) | C34: =COUNTIFS(Results!$B$2:$B$101,A34,Results!$AA$2:$AA$101,"PASS") | D34: =COUNTIFS(Results!$B$2:$B$101,A34,Results!$AA$2:$AA$101,"PARTIAL") | E34: =COUNTIFS(Results!$B$2:$B$101,A34,Results!$AA$2:$AA$101,"FAIL") | F34: =COUNTIFS(Results!$B$2:$B$101,A34,Results!$AA$2:$AA$101,"BLOCKED") | G34: =IF(B34=0,0,C34/B34)
A35: Scenario-based | B35: =COUNTIF(Results!$B$2:$B$101,A35) | C35: =COUNTIFS(Results!$B$2:$B$101,A35,Results!$AA$2:$AA$101,"PASS") | D35: =COUNTIFS(Results!$B$2:$B$101,A35,Results!$AA$2:$AA$101,"PARTIAL") | E35: =COUNTIFS(Results!$B$2:$B$101,A35,Results!$AA$2:$AA$101,"FAIL") | F35: =COUNTIFS(Results!$B$2:$B$101,A35,Results!$AA$2:$AA$101,"BLOCKED") | G35: =IF(B35=0,0,C35/B35)
A36: Multi-hop | B36: =COUNTIF(Results!$B$2:$B$101,A36) | C36: =COUNTIFS(Results!$B$2:$B$101,A36,Results!$AA$2:$AA$101,"PASS") | D36: =COUNTIFS(Results!$B$2:$B$101,A36,Results!$AA$2:$AA$101,"PARTIAL") | E36: =COUNTIFS(Results!$B$2:$B$101,A36,Results!$AA$2:$AA$101,"FAIL") | F36: =COUNTIFS(Results!$B$2:$B$101,A36,Results!$AA$2:$AA$101,"BLOCKED") | G36: =IF(B36=0,0,C36/B36)
A37: Source-awareness | B37: =COUNTIF(Results!$B$2:$B$101,A37) | C37: =COUNTIFS(Results!$B$2:$B$101,A37,Results!$AA$2:$AA$101,"PASS") | D37: =COUNTIFS(Results!$B$2:$B$101,A37,Results!$AA$2:$AA$101,"PARTIAL") | E37: =COUNTIFS(Results!$B$2:$B$101,A37,Results!$AA$2:$AA$101,"FAIL") | F37: =COUNTIFS(Results!$B$2:$B$101,A37,Results!$AA$2:$AA$101,"BLOCKED") | G37: =IF(B37=0,0,C37/B37)
A38: Synthesis | B38: =COUNTIF(Results!$B$2:$B$101,A38) | C38: =COUNTIFS(Results!$B$2:$B$101,A38,Results!$AA$2:$AA$101,"PASS") | D38: =COUNTIFS(Results!$B$2:$B$101,A38,Results!$AA$2:$AA$101,"PARTIAL") | E38: =COUNTIFS(Results!$B$2:$B$101,A38,Results!$AA$2:$AA$101,"FAIL") | F38: =COUNTIFS(Results!$B$2:$B$101,A38,Results!$AA$2:$AA$101,"BLOCKED") | G38: =IF(B38=0,0,C38/B38)
A39: Navigation | B39: =COUNTIF(Results!$B$2:$B$101,A39) | C39: =COUNTIFS(Results!$B$2:$B$101,A39,Results!$AA$2:$AA$101,"PASS") | D39: =COUNTIFS(Results!$B$2:$B$101,A39,Results!$AA$2:$AA$101,"PARTIAL") | E39: =COUNTIFS(Results!$B$2:$B$101,A39,Results!$AA$2:$AA$101,"FAIL") | F39: =COUNTIFS(Results!$B$2:$B$101,A39,Results!$AA$2:$AA$101,"BLOCKED") | G39: =IF(B39=0,0,C39/B39)
A40: False Premise | B40: =COUNTIF(Results!$B$2:$B$101,A40) | C40: =COUNTIFS(Results!$B$2:$B$101,A40,Results!$AA$2:$AA$101,"PASS") | D40: =COUNTIFS(Results!$B$2:$B$101,A40,Results!$AA$2:$AA$101,"PARTIAL") | E40: =COUNTIFS(Results!$B$2:$B$101,A40,Results!$AA$2:$AA$101,"FAIL") | F40: =COUNTIFS(Results!$B$2:$B$101,A40,Results!$AA$2:$AA$101,"BLOCKED") | G40: =IF(B40=0,0,C40/B40)
... A45: Procedure | B45: =COUNTIF(Results!$B$2:$B$101,A45) | C45: =COUNTIFS(Results!$B$2:$B$101,A45,Results!$AA$2:$AA$101,"PASS") | D45: =COUNTIFS(Results!$B$2:$B$101,A45,Results!$AA$2:$AA$101,"PARTIAL") | E45: =COUNTIFS(Results!$B$2:$B$101,A45,Results!$AA$2:$AA$101,"FAIL") | F45: =COUNTIFS(Results!$B$2:$B$101,A45,Results!$AA$2:$AA$101,"BLOCKED") | G45: =IF(B45=0,0,C45/B45)

Sheet Results
A1: Test Case ID | B1: Category | C1: Query | D1: Expected Answer | E1: Evidence | F1: Source Page | G1: Source Section | H1: Required Keywords / Key Concepts | I1: Retrieval Difficulty | J1: Expected Retrieval Type | K1: Is Answerable | L1: Expected Behavior | M1: Notes | N1: Document | O1: Actual Answer | P1: Cited Sources | Q1: Context Sources | R1: LLM Model | S1: Latency (s) | T1: Keyword Coverage | U1: Expected-Answer Recall | V1: Cited Expected Doc | W1: Page Match | X1: Suggested Status | Y1: Auto Reasons | Z1: Final Status | AA1: Effective Status | AB1: Defect ID | AC1: Tester Note
A2: LAW_A_001 | B2: Definition | C2: Theo giáo trình, đối tượng điều chỉnh của Luật lao động gồm những nhóm quan hệ nào? | D2: Gồm quan hệ lao động và các quan hệ liên quan chặt chẽ hoặc phát sinh từ quan hệ lao động. | E2: Căn cứ: phần “Bài 1 - Đối tượng điều chỉnh”, trang 3. Nội dung được tài liệu xác nhận: Gồm quan hệ lao động và các quan hệ liên quan chặt chẽ hoặc phát sinh từ quan hệ lao động. | F2: 3 | G2: Bài 1 - Đối tượng điều chỉnh | H2: quan hệ lao động | quan hệ liên quan | I2: Easy | J2: Single Chunk | K2: Yes | L2: Answer from document | N2: giao trinh Luat lao dong CB 2005 (1) | O2: Theo giáo trình, đối tượng điều chỉnh của Luật lao động bao gồm hai nhóm quan hệ xã hội [SOURCE_1]: 1. **Quan hệ lao động** [SOURCE_1]. 2. **Các quan hệ liên quan đến quan hệ lao động** (phát sinh trong quá trình sử dụng lao động) [SOURCE_1]. Cụ thể, đó là mối quan hệ xã hội phát sinh giữa một bên là người lao động làm công ăn lương với một bên là cá nhân hoặc tổ chức sử dụng, thuê mướn có trả công cho người lao động và các quan hệ khác có liên quan chặt chẽ hoặc phát sinh từ quan hệ lao động [SOURCE_1]. | P2: [SOURCE_1] giao trinh Luat lao dong CB 2005 (1) | tr.3 | BÀI 1 > KHÁI NIỆM LUẬT LAO ĐỘNG VIỆT NAM > I - ĐỐI TƯỢNG VÀ | 0.9984 | Q2: [SOURCE_1] giao trinh Luat lao dong CB 2005 (1) | tr.3 | BÀI 1 > KHÁI NIỆM LUẬT LAO ĐỘNG VIỆT NAM > I - ĐỐI TƯỢNG VÀ | 0.9984 [SOURCE_2] giao trinh Luat lao dong CB 2005 (1) | tr.7 | 2 - Phương pháp điều chỉnh của luật lao động | 0.9587 [SOURCE_3] giao trinh Luat lao dong CB 2005 (1) | tr.7 | (7) - Quan hệ về quản lý lao động | 0.9279 [SOURCE_4] giao trinh Luat lao dong CB 2005 (1) | tr.3 | a - Quan hệ lao động | 0.8305 [SOURCE_5] giao trinh Luat lao dong CB 2005 (1) | tr.6 | (4) Quan hệ về bảo hiểm xã hội | 0.8054 | R2: GeminiProvider | S2: 19 | T2: 1 | U2: 1 | V2: Yes | W2: Yes | X2: PASS | AA2: =IF(Z2="",X2,Z2)
A3: LAW_A_002 | B3: Definition | C3: Quan hệ lao động được giáo trình mô tả là gì? | D3: Là quan hệ giữa con người với con người trong lao động nhằm tạo ra các giá trị vật chất, tinh thần phục vụ bản thân và xã hội. | E3: Căn cứ: phần “Bài 1 - Quan hệ lao động”, trang 3. Nội dung được tài liệu xác nhận: Là quan hệ giữa con người với con người trong lao động nhằm tạo ra các giá trị vật chất, tinh thần phục vụ bản thân và xã hội. | F3: 3 | G3: Bài 1 - Quan hệ lao động | H3: lao động | giá trị vật chất | tinh thần | I3: Easy | J3: Single Chunk | K3: Yes | L3: Answer from document | N3: giao trinh Luat lao dong CB 2005 (1) | O3: Theo Giáo trình Luật Lao động cơ bản, quan hệ lao động được mô tả như sau: * Quan hệ lao động vừa có tính kinh tế, vừa có tính xã hội [SOURCE_1]. * Quan hệ giữa con người với con người trong lao động nhằm tạo ra những giá trị vật chất, tinh thần phục vụ chính bản thân và xã hội gọi là quan hệ lao động [SOURCE_3]. * Quan hệ lao động là biểu hiện một mặt của quan hệ sản xuất và chịu sự chi phối của quan hệ sở hữu [SOURCE_3]. * Ở đâu có tổ chức lao động, có hợp tác và phân công lao động thì ở đó tồn tại quan hệ lao động [SOURCE_3]. * Trong số các quan hệ lao động tồn tại trong đời sống xã hội, Luật lao động chủ yếu điều chỉnh quan hệ lao động giữa người lao động làm công ăn lương với người sử dụng lao động thuộc mọi thành phần kinh tế (xác lập trên cơ sở hợp đồng lao động) [SOURCE_3]. | P3: [SOURCE_1] giao trinh Luat lao dong CB 2005 (1) | tr.13 | Giáo trình Luật Lao động cơ bản | 0.9737 [SOURCE_3] giao trinh Luat lao dong CB 2005 (1) | tr.3 | a - Quan hệ lao động | 0.8496 | Q3: [SOURCE_1] giao trinh Luat lao dong CB 2005 (1) | tr.13 | Giáo trình Luật Lao động cơ bản | 0.9737 [SOURCE_2] giao trinh Luat lao dong CB 2005 (1) | tr.3 | a - Quan hệ lao động | 0.8655 [SOURCE_3] giao trinh Luat lao dong CB 2005 (1) | tr.3 | a - Quan hệ lao động | 0.8496 [SOURCE_4] luu-ban-nhap-tu-dong-3-4 | tr.69 | Điều 3. Giải thích từ ngữ ữ | 0.8055 [SOURCE_5] luu-ban-nhap-tu-dong-3-4 | tr.72 | Điều 7. Quan hệ lao động | 0.7175 | R3: GeminiProvider | S3: 26.6 | T3: 1 | U3: 1 | V3: Yes | W3: Yes | X3: PASS | AA3: =IF(Z3="",X3,Z3)
A4: LAW_A_003 | B4: List | C4: Giáo trình liệt kê những quan hệ nào liên quan đến quan hệ lao động? | D4: Gồm quan hệ về việc làm, học nghề, bồi thường thiệt hại, bảo hiểm xã hội, quan hệ với Công đoàn/đại diện tập thể lao động, giải quyết tranh chấp và đình công, và quản lý lao động. | E4: Căn cứ: phần “Bài 1 - Các quan hệ liên quan”, trang 5. Nội dung được tài liệu xác nhận: Gồm quan hệ về việc làm, học nghề, bồi thường thiệt hại, bảo hiểm xã hội, quan hệ với Công đoàn/đại diện tập thể lao động, giải quyết tranh chấp và đình công, và quản lý lao động. | F4: 5 | G4: Bài 1 - Các quan hệ liên quan | H4: việc làm | học nghề | bồi thường | BHXH | công đoàn | tranh chấp | quản lý | I4: Easy | J4: Single Chunk | K4: Yes | L4: Answer from document | N4: giao trinh Luat lao dong CB 2005 (1) | O4: Theo giáo trình, các quan hệ có liên quan chặt chẽ với quan hệ lao động bao gồm [SOURCE_1]: * Quan hệ về việc làm [SOURCE_1]; * Quan hệ học nghề [SOURCE_1]; * Quan hệ về bồi thường thiệt hại [SOURCE_1]; * Quan hệ về bảo hiểm xã hội [SOURCE_1]; * Quan hệ giữa người sử dụng lao động với tổ chức Công đoàn, đại diện của tập thể người lao động [SOURCE_1]; * Quan hệ về giải quyết các tranh chấp lao động và các cuộc đình công [SOURCE_1]; * Quan hệ về quản lý lao động [SOURCE_1]. | P4: [SOURCE_1] giao trinh Luat lao dong CB 2005 (1) | tr.4 | b - Các quan hệ liên quan đến quan hệ lao động | 0.9891 | Q4: [SOURCE_1] giao trinh Luat lao dong CB 2005 (1) | tr.4 | b - Các quan hệ liên quan đến quan hệ lao động | 0.9891 [SOURCE_2] giao trinh Luat lao dong CB 2005 (1) | tr.13 | Giáo trình Luật Lao động cơ bản | 0.9326 [SOURCE_3] giao trinh Luat lao dong CB 2005 (1) | tr.3 | a - Quan hệ lao động | 0.9083 [SOURCE_4] luu-ban-nhap-tu-dong-3-4 | tr.72 | Điều 7. Quan hệ lao động | 0.8941 [SOURCE_5] giao trinh Luat lao dong CB 2005 (1) | tr.3 | a - Quan hệ lao động | 0.891 | R4: GeminiProvider | S4: 22.5 | T4: 1 | U4: 1 | V4: Yes | W4: Yes | X4: PASS | AA4: =IF(Z4="",X4,Z4)
A5: LAW_A_004 | B5: Definition | C5: Theo giáo trình, quan hệ pháp luật lao động là gì? | D5: Là các quan hệ phát sinh trong quá trình sử dụng sức lao động, được các quy phạm pháp luật lao động điều chỉnh. | E5: Căn cứ: phần “Bài 2 - Khái niệm”, trang 14. Nội dung được tài liệu xác nhận: Là các quan hệ phát sinh trong quá trình sử dụng sức lao động, được các quy phạm pháp luật lao động điều chỉnh. | F5: 14 | G5: Bài 2 - Khái niệm | H5: sử dụng sức lao động | quy phạm pháp luật lao động | I5: Easy | J5: Single Chunk | K5: Yes | L5: Answer from document | N5: giao trinh Luat lao dong CB 2005 (1) | O5: Theo giáo trình, quan hệ pháp luật lao động là các quan hệ phát sinh trong quá trình sử dụng sức lao động của người lao động ở các cơ quan Nhà nước, các tổ chức, các hợp tác xã, các doanh nghiệp thuộc mọi thành phần kinh tế và các gia đình hay cá nhân có thuê mướn lao động, được các quy phạm pháp luật lao động điều chỉnh [SOURCE_2]. Quan hệ pháp luật lao động thể hiện sự ràng buộc trách nhiệm giữa người lao động làm công ăn lương với người sử dụng lao động [SOURCE_2]: * **Đối với người lao động:** Khi tham gia quan hệ này, người lao động phải hoàn thành công việc như đã thỏa thuận trong hợp đồng lao động, chấp hành nội quy lao động và chịu sự quản lý, điều hành của người chủ [SOURCE_2]. * **Đối với người sử dụng lao động:** Phải đảm bảo trả lương và các chế độ khác cho người lao động theo thỏa thuận trong hợp đồng lao động phù hợp với pháp luật và thỏa ước lao động tập thể [SOURCE_2]. | P5: [SOURCE_2] giao trinh Luat lao dong CB 2005 (1) | tr.14 | BÀI 2 > QUAN HỆ PHÁP LUẬT LAO ĐỘNG > I - KHÁI NIỆM VÀ ĐẶC ĐI | 0.9835 | Q5: [SOURCE_1] giao trinh Luat lao dong CB 2005 (1) | tr.13 | Giáo trình Luật Lao động cơ bản | 0.9936 [SOURCE_2] giao trinh Luat lao dong CB 2005 (1) | tr.14 | BÀI 2 > QUAN HỆ PHÁP LUẬT LAO ĐỘNG > I - KHÁI NIỆM VÀ ĐẶC ĐI | 0.9835 [SOURCE_3] giao trinh Luat lao dong CB 2005 (1) | tr.14 | 2. Đặc điểm của quan hệ pháp luật lao động | 0.9708 [SOURCE_4] giao trinh Luat lao dong CB 2005 (1) | tr.14 | 2. Đặc điểm của quan hệ pháp luật lao động | 0.9608 [SOURCE_5] giao trinh Luat lao dong CB 2005 (1) | tr.18 | 2. Nội dung của quan hệ pháp luật lao động | 0.9575 | R5: GeminiProvider | S5: 17.6 | T5: 1 | U5: 1 | V5: Yes | W5: Yes | X5: PASS | AA5: =IF(Z5="",X5,Z5)
A6: LAW_A_005 | B6: Direct Fact | C6: Ba loại quan hệ về việc làm chủ yếu được giáo trình nêu là gì? | D6: Quan hệ bảo đảm việc làm giữa Nhà nước và NLĐ; giữa NSDLĐ và NLĐ; và giữa NLĐ với các trung tâm dịch vụ việc làm. | E6: Căn cứ: phần “Bài 1 - Quan hệ việc làm”, trang 5. Nội dung được tài liệu xác nhận: Quan hệ bảo đảm việc làm giữa Nhà nước và NLĐ; giữa NSDLĐ và NLĐ; và giữa NLĐ với các trung tâm dịch vụ việc làm. | F6: 5 | G6: Bài 1 - Quan hệ việc làm | H6: Nhà nước | NSDLĐ | trung tâm dịch vụ việc làm | I6: Easy | J6: Single Chunk | K6: Yes | L6: Answer from document | N6: giao trinh Luat lao dong CB 2005 (1) | O6: Dựa trên tài liệu được cung cấp, ba loại quan hệ về việc làm chủ yếu bao gồm: 1. Quan hệ về đảm bảo việc làm giữa Nhà nước và người lao động [SOURCE_1]. 2. Quan hệ về đảm bảo việc làm giữa người sử dụng lao động và người lao động [SOURCE_1]. 3. Quan hệ giữa người lao động và các trung tâm dịch vụ việc làm [SOURCE_1]. | P6: [SOURCE_1] giao trinh Luat lao dong CB 2005 (1) | tr.5 | (1) Quan hệ về việc làm | 0.9905 | Q6: [SOURCE_1] giao trinh Luat lao dong CB 2005 (1) | tr.5 | (1) Quan hệ về việc làm | 0.9905 [SOURCE_2] giao trinh Luat lao dong CB 2005 (1) | tr.4 | b - Các quan hệ liên quan đến quan hệ lao động | 0.5222 | R6: GeminiProvider | S6: 20.3 | T6: 1 | U6: 1 | V6: Yes | W6: Yes | X6: PASS | AA6: =IF(Z6="",X6,Z6)
A7: LAW_A_006 | B7: Concept | C7: Quan hệ học nghề có thể tồn tại dưới những dạng nào? | D7: Có thể là quan hệ độc lập hoặc là quan hệ phụ thuộc quan hệ lao động. | E7: Căn cứ: phần “Bài 1 - Quan hệ học nghề”, trang 5. Nội dung được tài liệu xác nhận: Có thể là quan hệ độc lập hoặc là quan hệ phụ thuộc quan hệ lao động. | F7: 5 | G7: Bài 1 - Quan hệ học nghề | H7: độc lập | phụ thuộc quan hệ lao động | I7: Easy | J7: Single Chunk | K7: Yes | L7: Answer from document | N7: giao trinh Luat lao dong CB 2005 (1) | O7: Dựa trên tài liệu được cung cấp, quan hệ học nghề vừa có thể là một quan hệ độc lập, vừa có thể là một quan hệ phụ thuộc quan hệ lao động [SOURCE_1]. | P7: [SOURCE_1] giao trinh Luat lao dong CB 2005 (1) | tr.5 | (2) Quan hệ học nghề | 0.8816 | Q7: [SOURCE_1] giao trinh Luat lao dong CB 2005 (1) | tr.5 | (2) Quan hệ học nghề | 0.8816 [SOURCE_2] giao trinh Luat lao dong CB 2005 (1) | tr.5 | (2) Quan hệ học nghề | 0.4338 | R7: GeminiProvider | S7: 19 | T7: 1 | U7: 1 | V7: Yes | W7: Yes | X7: PASS | AA7: =IF(Z7="",X7,Z7)
A8: LAW_A_007 | B8: Definition | C8: Theo giáo trình, tiền lương được nhìn nhận như thế nào trong quan hệ lao động? | D8: Tiền lương được xem là giá cả của sức lao động và việc trả lương dựa trên thỏa thuận, trong khuôn khổ pháp luật. | E8: Căn cứ: phần “Bài 1/Bài 6 - Tiền lương”, trang None. Nội dung được tài liệu xác nhận: Tiền lương được xem là giá cả của sức lao động và việc trả lương dựa trên thỏa thuận, trong khuôn khổ pháp luật. | G8: Bài 1/Bài 6 - Tiền lương | H8: giá cả sức lao động | thỏa thuận | I8: Easy | J8: Single Chunk | K8: Yes | L8: Answer from document | N8: giao trinh Luat lao dong CB 2005 (1) | O8: Theo tài liệu được cung cấp, tiền lương trong quan hệ lao động được nhìn nhận và quy định như sau: * **Là một mục tiêu kinh tế:** Trong quan hệ lao động, tiền lương được nhìn nhận là một trong những mục tiêu kinh tế (bên cạnh lợi nhuận, sự tăng trưởng trong sản xuất, kinh doanh) mà Luật lao động phải xem xét kết hợp hài hòa với việc giải quyết các vấn đề xã hội [SOURCE_1]. * **Định nghĩa về tiền lương:** * Tiền lương được hiểu là số lượng tiền tệ mà người sử dụng lao động trả cho người lao động khi người lao động hoàn thành công việc theo chức năng, nhiệm vụ do pháp luật quy định, hoặc do hai bên đã thỏa thuận trong hợp đồng lao động [SOURCE_2]. * Tiền lương cũng là số tiền trả theo thỏa thuận để thực hiện công việc, bao gồm mức lương theo công việc hoặc chức danh, phụ cấp lương và các khoản bổ sung khác [SOURCE_3]. * **Cơ chế xác định và trả lương:** * Tiền lương do hai bên thỏa thuận trong hợp đồng lao động và được trả theo năng suất lao động, chất lượng và hiệu quả công việc [SOURCE_2]. * Mức lương theo công việc hoặc chức danh không được thấp hơn mức lương tối thiểu do Nhà nước quy định [SOURCE_2], [SOURCE_3]. * Lương được trả bằng tiền mặt, hoặc có thể trả một phần bằng séc/ngân phiếu do Nhà nước phát hành theo thỏa thuận của hai bên với điều kiện không gây thiệt hại, phiền hà cho người lao động [SOURCE_2]. * Người sử dụng lao động phải bảo đảm trả lương bình đẳng, không phân biệt giới tính đối với người lao động làm công việc có giá trị như nhau [SOURCE_3]. | P8: [SOURCE_1] giao trinh Luat lao dong CB 2005 (1) | tr.13 | Giáo trình Luật Lao động cơ bản | 0.7146 [SOURCE_2] giao trinh Luat lao dong CB 2005 (1) | tr.58 | BÀI 6 > TIỀN LƯƠNG > I. KHÁI QUÁT CHUNG VỀ TIỀN LƯƠNG > 1. Đ | 0.4023 [SOURCE_3] luu-ban-nhap-tu-dong-3-4 | tr.31 | Chương VI > Điều 90. Tiền lương | 0.3612 | Q8: [SOURCE_1] giao trinh Luat lao dong CB 2005 (1) | tr.13 | Giáo trình Luật Lao động cơ bản | 0.7146 [SOURCE_2] giao trinh Luat lao dong CB 2005 (1) | tr.58 | BÀI 6 > TIỀN LƯƠNG > I. KHÁI QUÁT CHUNG VỀ TIỀN LƯƠNG > 1. Đ | 0.4023 [SOURCE_3] luu-ban-nhap-tu-dong-3-4 | tr.31 | Chương VI > Điều 90. Tiền lương | 0.3612 | R8: GeminiProvider | S8: 22.6 | T8: 0.5 | U8: 0.68421053 | V8: Yes | W8: n/a | X8: PARTIAL | Y8: Thiếu từ khóa (50%) | AA8: =IF(Z8="",X8,Z8)
A9: LAW_A_008 | B9: Direct Fact | C9: Theo giáo trình, làm thêm vào ngày thường được trả ít nhất bao nhiêu phần trăm? | D9: Ít nhất bằng 150% đơn giá tiền lương hoặc tiền lương thực trả của công việc đang làm. | E9: Căn cứ: phần “Bài 6 - Trả lương làm thêm giờ”, trang 59. Nội dung được tài liệu xác nhận: Ít nhất bằng 150% đơn giá tiền lương hoặc tiền lương thực trả của công việc đang làm. | F9: 59 | G9: Bài 6 - Trả lương làm thêm giờ | H9: 150% | ngày thường | I9: Medium | J9: Single Chunk | K9: Yes | L9: Answer from document | N9: giao trinh Luat lao dong CB 2005 (1) | O9: Theo tài liệu được cung cấp, người lao động làm thêm giờ vào ngày thường được trả lương ít nhất bằng **150%** tính theo đơn giá tiền lương hoặc tiền lương theo công việc đang làm [SOURCE_1][SOURCE_2][SOURCE_3][SOURCE_4][SOURCE_5]. | P9: [SOURCE_1] so-tay-kien-thuc-phap-luat-lao-dong-cdi | tr.19 | Trả lời: | 0.9585 [SOURCE_2] giao trinh Luat lao dong CB 2005 (1) | tr.59 | 4. Trả lương khi làm thêm giờ | 0.9547 [SOURCE_3] Văn-bản-hợp-nhất-18-VBHN-VPQH | tr.38 | Điều 98. Tiền lương làm thêm giờ, làm việc vào ban đêm | 0.9278 [SOURCE_4] ILO-VCCI_Labour-Law-Guide-Book-V04-Final | tr.100 | 1. Tiền lương làm thêm giờ225 > (a) Đối với NLĐ hưởng lương | 0.9243 [SOURCE_5] giao trinh Luat lao dong CB 2005 (1) | tr.80 | · Các điều kiện và nguyên tắc làm thêm đến 300 giờ trong một | 0.8973 | Q9: [SOURCE_1] so-tay-kien-thuc-phap-luat-lao-dong-cdi | tr.19 | Trả lời: | 0.9585 [SOURCE_2] giao trinh Luat lao dong CB 2005 (1) | tr.59 | 4. Trả lương khi làm thêm giờ | 0.9547 [SOURCE_3] Văn-bản-hợp-nhất-18-VBHN-VPQH | tr.38 | Điều 98. Tiền lương làm thêm giờ, làm việc vào ban đêm | 0.9278 [SOURCE_4] ILO-VCCI_Labour-Law-Guide-Book-V04-Final | tr.100 | 1. Tiền lương làm thêm giờ225 > (a) Đối với NLĐ hưởng lương | 0.9243 [SOURCE_5] giao trinh Luat lao dong CB 2005 (1) | tr.80 | · Các điều kiện và nguyên tắc làm thêm đến 300 giờ trong một | 0.8973 | R9: GeminiProvider | S9: 19.8 | T9: 1 | U9: 0.93333333 | V9: Yes | W9: Yes | X9: PASS | AA9: =IF(Z9="",X9,Z9)
A10: LAW_A_009 | B10: Direct Fact | C10: Theo giáo trình, làm thêm vào ngày nghỉ hằng tuần được trả ít nhất bao nhiêu? | D10: Ít nhất bằng 200%. | E10: Căn cứ: phần “Bài 6 - Trả lương làm thêm giờ”, trang 59. Nội dung được tài liệu xác nhận: Ít nhất bằng 200%. | F10: 59 | G10: Bài 6 - Trả lương làm thêm giờ | H10: 200% | ngày nghỉ hàng tuần | I10: Medium | J10: Single Chunk | K10: Yes | L10: Answer from document | N10: giao trinh Luat lao dong CB 2005 (1) | O10: Theo giáo trình, người lao động làm thêm giờ vào ngày nghỉ hàng tuần được trả lương ít nhất bằng 200% tính theo đơn giá tiền lương hoặc tiền lương thực trả của công việc đang làm [SOURCE_4], [SOURCE_5]. | P10: [SOURCE_4] giao trinh Luat lao dong CB 2005 (1) | tr.59 | 4. Trả lương khi làm thêm giờ | 0.9096 [SOURCE_5] giao trinh Luat lao dong CB 2005 (1) | tr.80 | · Các điều kiện và nguyên tắc làm thêm đến 300 giờ trong một | 0.8598 | Q10: [SOURCE_1] so-tay-kien-thuc-phap-luat-lao-dong-cdi | tr.19 | Trả lời: | 0.9454 [SOURCE_2] Văn-bản-hợp-nhất-18-VBHN-VPQH | tr.38 | Điều 98. Tiền lương làm thêm giờ, làm việc vào ban đêm | 0.9207 [SOURCE_3] ILO-VCCI_Labour-Law-Guide-Book-V04-Final | tr.100 | 1. Tiền lương làm thêm giờ225 > (a) Đối với NLĐ hưởng lương | 0.9207 [SOURCE_4] giao trinh Luat lao dong CB 2005 (1) | tr.59 | 4. Trả lương khi làm thêm giờ | 0.9096 [SOURCE_5] giao trinh Luat lao dong CB 2005 (1) | tr.80 | · Các điều kiện và nguyên tắc làm thêm đến 300 giờ trong một | 0.8598 | R10: GeminiProvider | S10: 17.5 | T10: 1 | U10: 1 | V10: Yes | W10: Yes | X10: PASS | AA10: =IF(Z10="",X10,Z10)
A11: LAW_A_010 | B11: Direct Fact | C11: Theo giáo trình, làm thêm vào ngày lễ/ngày nghỉ hưởng lương được trả ít nhất bao nhiêu? | D11: Ít nhất bằng 300% theo quy định được tài liệu trình bày. | E11: Căn cứ: phần “Bài 6 - Trả lương làm thêm giờ”, trang 59. Nội dung được tài liệu xác nhận: Ít nhất bằng 300% theo quy định được tài liệu trình bày. | F11: 59 | G11: Bài 6 - Trả lương làm thêm giờ | H11: 300% | ngày lễ | nghỉ hưởng lương | I11: Medium | J11: Single Chunk | K11: Yes | L11: Answer from document | N11: giao trinh Luat lao dong CB 2005 (1) | O11: Theo giáo trình, người lao động làm thêm vào ngày lễ, ngày nghỉ có hưởng lương được trả lương ít nhất bằng 300% tính theo đơn giá tiền lương hoặc tiền lương thực trả của công việc đang làm [SOURCE_2]. (Thông tin này cũng đồng nhất với các văn bản pháp luật và tài liệu hướng dẫn liên quan [SOURCE_1], [SOURCE_3], [SOURCE_4], [SOURCE_5]). | P11: [SOURCE_1] so-tay-kien-thuc-phap-luat-lao-dong-cdi | tr.19 | Trả lời: | 0.9537 [SOURCE_2] giao trinh Luat lao dong CB 2005 (1) | tr.59 | 4. Trả lương khi làm thêm giờ | 0.9412 [SOURCE_3] Văn-bản-hợp-nhất-18-VBHN-VPQH | tr.38 | Điều 98. Tiền lương làm thêm giờ, làm việc vào ban đêm | 0.9356 [SOURCE_4] luu-ban-nhap-tu-dong-3-4 | tr.424 | Điều 25. Tiền lương làm thêm giờ, làm việc vào ban đêm | 0.9305 [SOURCE_5] ILO-VCCI_Labour-Law-Guide-Book-V04-Final | tr.100 | 1. Tiền lương làm thêm giờ225 > (a) Đối với NLĐ hưởng lương | 0.9082 | Q11: [SOURCE_1] so-tay-kien-thuc-phap-luat-lao-dong-cdi | tr.19 | Trả lời: | 0.9537 [SOURCE_2] giao trinh Luat lao dong CB 2005 (1) | tr.59 | 4. Trả lương khi làm thêm giờ | 0.9412 [SOURCE_3] Văn-bản-hợp-nhất-18-VBHN-VPQH | tr.38 | Điều 98. Tiền lương làm thêm giờ, làm việc vào ban đêm | 0.9356 [SOURCE_4] luu-ban-nhap-tu-dong-3-4 | tr.424 | Điều 25. Tiền lương làm thêm giờ, làm việc vào ban đêm | 0.9305 [SOURCE_5] ILO-VCCI_Labour-Law-Guide-Book-V04-Final | tr.100 | 1. Tiền lương làm thêm giờ225 > (a) Đối với NLĐ hưởng lương | 0.9082 | R11: GeminiProvider | S11: 18.6 | T11: 0.66666667 | U11: 0.625 | V11: Yes | W11: Yes | X11: PARTIAL | Y11: Thiếu từ khóa (67%) | AA11: =IF(Z11="",X11,Z11)
A12: LAW_A_011 | B12: Rule | C12: Giới hạn làm thêm giờ mà giáo trình nêu là bao nhiêu? | D12: Không quá 4 giờ trong một ngày, 200 giờ trong một năm; một số trường hợp đặc biệt không quá 300 giờ trong một năm. | E12: Căn cứ: phần “Bài 7 - Làm thêm giờ”, trang 79. Nội dung được tài liệu xác nhận: Không quá 4 giờ trong một ngày, 200 giờ trong một năm; một số trường hợp đặc biệt không quá 300 giờ trong một năm. | F12: 79 | G12: Bài 7 - Làm thêm giờ | H12: 4 giờ/ngày | 200 giờ/năm | 300 giờ/năm | I12: Medium | J12: Single Chunk | K12: Yes | L12: Answer from document | N12: giao trinh Luat lao dong CB 2005 (1) | O12: Theo các tài liệu được cung cấp, giới hạn số giờ làm thêm được quy định cụ thể theo ngày, theo tháng và theo năm như sau: **1. Giới hạn theo ngày:** * Tổng số giờ làm thêm không quá **50% số giờ làm việc bình thường trong 01 ngày** khi làm thêm vào ngày làm việc bình thường [SOURCE_3], [SOURCE_4]. * Trường hợp áp dụng quy định thời giờ làm việc bình thường theo tuần, làm việc không trọn thời gian, hoặc làm thêm vào ngày nghỉ lễ, tết, ngày nghỉ hằng tuần thì tổng số giờ làm việc bình thường và số giờ làm thêm **không quá 12 giờ trong 01 ngày** [SOURCE_3], [SOURCE_4]. **2. Giới hạn theo tháng:** * Theo quy định cũ (Điều 106) là **không quá 30 giờ trong 01 tháng** [SOURCE_3]. * Từ ngày 01/01/2021, tổng số giờ làm thêm của người lao động **không quá 40 giờ trong 01 tháng** [SOURCE_4]. **3. Giới hạn theo năm:** * Tổng số giờ làm thêm **không quá 200 giờ trong 01 năm** [SOURCE_3]. * Đối với một số trường hợp đặc biệt do Chính phủ quy định (như giải quyết công việc đòi hỏi trình độ kỹ thuật cao mà thị trường không cung ứng đủ, công việc cấp bách không thể trì hoãn, dịch vụ công, khám chữa bệnh, giáo dục,...), số giờ làm thêm được phép tối đa **không quá 300 giờ trong 01 năm** [SOURCE_1], [SOURCE_2], [SOURCE_3 | P12: [SOURCE_1] ILO-VCCI_Labour-Law-Guide-Book-V04-Final | tr.112 | (ii) Giới hạn số giờ làm thêm trong năm | 0.6783 [SOURCE_2] ILO-VCCI_Labour-Law-Guide-Book-V04-Final | tr.112 | (ii) Giới hạn số giờ làm thêm trong năm | 0.4942 [SOURCE_3] luu-ban-nhap-tu-dong-3-4 | tr.101 | Điều 106. Làm thêm giờ | 0.4728 [SOURCE_4] ILO-VCCI_Labour-Law-Guide-Book-V04-Final | tr.111 | (i) Giới hạn số giờ làm thêm trong ngày và trong tháng | 0.436 | Q12: [SOURCE_1] ILO-VCCI_Labour-Law-Guide-Book-V04-Final | tr.112 | (ii) Giới hạn số giờ làm thêm trong năm | 0.6783 [SOURCE_2] ILO-VCCI_Labour-Law-Guide-Book-V04-Final | tr.112 | (ii) Giới hạn số giờ làm thêm trong năm | 0.4942 [SOURCE_3] luu-ban-nhap-tu-dong-3-4 | tr.101 | Điều 106. Làm thêm giờ | 0.4728 [SOURCE_4] ILO-VCCI_Labour-Law-Guide-Book-V04-Final | tr.111 | (i) Giới hạn số giờ làm thêm trong ngày và trong tháng | 0.436 | R12: GeminiProvider | S12: 24.6 | T12: 0 | U12: 1 | V12: No | W12: No | X12: PARTIAL | Y12: Thiếu từ khóa (0%); Không trích tài liệu mong đợi (không có trong ngữ cảnh); Không trích đúng trang 79 (±1) | AA12: =IF(Z12="",X12,Z12)
A13: LAW_A_012 | B13: Concept | C13: Vì sao phương pháp thỏa thuận có vai trò quan trọng trong Luật lao động theo giáo trình? | D13: Vì quan hệ lao động có bản chất tự do thương lượng; các bên thỏa thuận trên cơ sở tự nguyện, bình đẳng để cùng có lợi và thực hiện nghĩa vụ. | E13: Căn cứ: phần “Bài 1 - Phương pháp điều chỉnh” Nội dung được tài liệu xác nhận: Vì quan hệ lao động có bản chất tự do thương lượng; các bên thỏa thuận trên cơ sở tự nguyện, bình đẳng để cùng có lợi và thực hiện nghĩa vụ. | G13: Bài 1 - Phương pháp điều chỉnh | H13: thỏa thuận | tự nguyện | bình đẳng | cùng có lợi | I13: Medium | J13: Single Chunk | K13: Yes | L13: Answer from document | N13: giao trinh Luat lao dong CB 2005 (1) | O13: Theo giáo trình, phương pháp thỏa thuận có vai trò quan trọng trong Luật lao động vì các lý do sau: * **Xuất phát từ bản chất của quan hệ lao động:** Bản chất của quan hệ lao động là tự do thương lượng [SOURCE_2]. * **Phạm vi áp dụng chủ đạo:** Phương pháp này chủ yếu áp dụng trong trường hợp xác lập quan hệ lao động giữa người lao động với người sử dụng lao động, và trong việc xác lập thỏa ước lao động tập thể [SOURCE_2]. * **Bảo đảm lợi ích và nghĩa vụ của các bên:** Khi tham gia vào quan hệ lao động, các bên cùng nhau thỏa thuận các vấn đề liên quan trong quá trình lao động trên cơ sở tự nguyện, bình đẳng [SOURCE_1], [SOURCE_2]. Việc này nhằm đảm bảo cho cả hai bên cùng có lợi và tạo điều kiện thuận lợi để các bên thực hiện tốt các | P13: [SOURCE_1] giao trinh Luat lao dong CB 2005 (1) | tr.7 | a - Phương pháp thỏa thuận | 0.9808 [SOURCE_2] giao trinh Luat lao dong CB 2005 (1) | tr.7 | a - Phương pháp thỏa thuận | 0.9449 | Q13: [SOURCE_1] giao trinh Luat lao dong CB 2005 (1) | tr.7 | a - Phương pháp thỏa thuận | 0.9808 [SOURCE_2] giao trinh Luat lao dong CB 2005 (1) | tr.7 | a - Phương pháp thỏa thuận | 0.9449 [SOURCE_3] giao trinh Luat lao dong CB 2005 (1) | tr.49 | 4. Ý nghĩa của thỏa ước lao động tập thể | 0.3944 | R13: GeminiProvider | S13: 27.4 | T13: 1 | U13: 1 | V13: Yes | W13: n/a | X13: PASS | AA13: =IF(Z13="",X13,Z13)
A14: LAW_A_013 | B14: Comparison | C14: Phương pháp thỏa thuận trong Luật lao động khác Luật dân sự ở điểm nào theo giáo trình? | D14: Giáo trình cho rằng trong dân sự các chủ thể bình đẳng và độc lập về địa vị kinh tế nên thỏa thuận được sử dụng triệt để; trong lao động, thỏa thuận chịu ảnh hưởng bởi quan hệ phụ thuộc và các giới hạn bảo vệ lao động. | E14: Căn cứ: phần “Bài 1 - Phương pháp điều chỉnh” Nội dung được tài liệu xác nhận: Giáo trình cho rằng trong dân sự các chủ thể bình đẳng và độc lập về địa vị kinh tế nên thỏa thuận được sử dụng triệt để; trong lao động, thỏa thuận chịu ảnh hưởng bởi quan hệ phụ thuộc và các giới hạn bảo vệ lao động. | G14: Bài 1 - Phương pháp điều chỉnh | H14: dân sự | lao động | bình đẳng | phụ thuộc | I14: Medium | J14: Multiple Chunks | K14: Yes | L14: Answer from document | N14: giao trinh Luat lao dong CB 2005 (1) | O14: Dựa trên tài liệu được cung cấp, phương pháp thỏa thuận trong Luật lao động khác với Luật dân sự ở các điểm sau [SOURCE_1]: * **Trong Luật dân sự:** * Các chủ thể tham gia quan hệ xã hội bình đẳng và độc lập với nhau về địa vị kinh tế [SOURCE_1]. * Phương pháp thỏa thuận được sử dụng triệt để và tác động lên các quan hệ dân sự trong suốt quá trình từ khi xác lập đến khi chấm dứt [SOURCE_1]. * **Trong Luật lao động:** * Các chủ thể tham gia vào quan hệ lao động không bình đẳng về địa vị và không độc lập với nhau về tổ chức [SOURCE_1]. * Nhà nước bằng pháp luật đặt ra những quy định nhằm bảo vệ và nâng cao vị trí của người lao động để họ bình đẳng với người sử dụng lao động [SOURCE_1]. * Tuy là sự tự do, thương lượng, tự nguyện thỏa thuận trong khuôn khổ pháp luật, nhưng trong quan hệ lao động luôn có yếu tố quản lý [SOURCE_1]. | P14: [SOURCE_1] giao trinh Luat lao dong CB 2005 (1) | tr.7 | a - Phương pháp thỏa thuận | 0.9941 | Q14: [SOURCE_1] giao trinh Luat lao dong CB 2005 (1) | tr.7 | a - Phương pháp thỏa thuận | 0.9941 [SOURCE_2] giao trinh Luat lao dong CB 2005 (1) | tr.7 | a - Phương pháp thỏa thuận | 0.8212 | R14: GeminiProvider | S14: 29.2 | T14: 0.75 | U14: 0.73684211 | V14: Yes | W14: n/a | X14: PASS | AA14: =IF(Z14="",X14,Z14)
A15: LAW_A_014 | B15: Concept | C15: Quan hệ bồi thường thiệt hại trong lao động phát sinh khi nào? | D15: Phát sinh khi một chủ thể trong quá trình thực hiện quyền, nghĩa vụ lao động gây thiệt hại về sức khỏe, tính mạng, tài sản hoặc lợi ích của bên kia. | E15: Căn cứ: phần “Bài 1 - Bồi thường thiệt hại”, trang 6. Nội dung được tài liệu xác nhận: Phát sinh khi một chủ thể trong quá trình thực hiện quyền, nghĩa vụ lao động gây thiệt hại về sức khỏe, tính mạng, tài sản hoặc lợi ích của bên kia. | F15: 6 | G15: Bài 1 - Bồi thường thiệt hại | H15: thiệt hại | sức khỏe | tính mạng | tài sản | I15: Medium | J15: Single Chunk | K15: Yes | L15: Answer from document | N15: giao trinh Luat lao dong CB 2005 (1) | O15: Theo tài liệu được cung cấp, quan hệ bồi thường thiệt hại trong lao động phát sinh khi các chủ thể khi tham gia quan hệ lao động thực hiện các quyền và nghĩa vụ lao động, mà một trong các chủ thể gây thiệt hại về sức khỏe, tính mạng, tài sản, hoặc lợi ích của bên kia [SOURCE_1]. | P15: [SOURCE_1] giao trinh Luat lao dong CB 2005 (1) | tr.5 | (2) Quan hệ học nghề | 0.9279 | Q15: [SOURCE_1] giao trinh Luat lao dong CB 2005 (1) | tr.5 | (2) Quan hệ học nghề | 0.9279 [SOURCE_2] giao trinh Luat lao dong CB 2005 (1) | tr.5 | (2) Quan hệ học nghề | 0.8897 [SOURCE_3] giao trinh Luat lao dong CB 2005 (1) | tr.95 | - Có quan hệ nhân quả giữa hành vi vi phạm và thiệt hại tài | 0.5862 [SOURCE_4] luu-ban-nhap-tu-dong-3-4 | tr.41 | Mục 2. TRÁCH NHIỆM VẬT CHẤT > Điều 129. Bồi thường thiệt hại | 0.411 | R15: GeminiProvider | S15: 17.9 | T15: 1 | U15: 0.92 | V15: Yes | W15: Yes | X15: PASS | AA15: =IF(Z15="",X15,Z15)
A16: LAW_A_015 | B16: Scenario-based | C16: Một NLĐ gây thiệt hại tài sản cho NSDLĐ khi thực hiện nghĩa vụ lao động. Theo cách phân loại của giáo trình, đây thuộc nhóm quan hệ nào? | D16: Thuộc quan hệ về bồi thường thiệt hại liên quan đến quan hệ lao động. | E16: Căn cứ: phần “Bài 1 - Bồi thường thiệt hại”, trang 5. Nội dung được tài liệu xác nhận: Thuộc quan hệ về bồi thường thiệt hại liên quan đến quan hệ lao động. | F16: 5 | G16: Bài 1 - Bồi thường thiệt hại | H16: bồi thường thiệt hại | tài sản | I16: Hard | J16: Single Chunk | K16: Yes | L16: Answer from document | N16: giao trinh Luat lao dong CB 2005 (1) | O16: Theo cách phân loại của giáo trình, trường hợp người lao động gây thiệt hại tài sản cho người sử dụng lao động khi thực hiện nghĩa vụ lao động thuộc nhóm **Quan hệ bồi thường thiệt hại tài sản** [SOURCE_1] (thuộc nhóm tổng quát là **Quan hệ về bồi thường thiệt hại** [SOURCE_2]). Cụ thể, khi thực hiện các quyền và nghĩa vụ lao động, nếu một trong các chủ thể gây thiệt hại tài sản cho bên kia thì sẽ phát sinh quan hệ về bồi thường thiệt hại [SOURCE_2], và quan hệ bồi thường thiệt hại tài sản là một trong ba loại của quan hệ pháp luật về bồi thường thiệt hại này [SOURCE_1]. | P16: [SOURCE_1] giao trinh Luat lao dong CB 2005 (1) | tr.5 | (2) Quan hệ học nghề | 0.9491 [SOURCE_2] giao trinh Luat lao dong CB 2005 (1) | tr.5 | (2) Quan hệ học nghề | 0.8208 | Q16: [SOURCE_1] giao trinh Luat lao dong CB 2005 (1) | tr.5 | (2) Quan hệ học nghề | 0.9491 [SOURCE_2] giao trinh Luat lao dong CB 2005 (1) | tr.5 | (2) Quan hệ học nghề | 0.8208 [SOURCE_3] giao trinh Luat lao dong CB 2005 (1) | tr.95 | - Có quan hệ nhân quả giữa hành vi vi phạm và thiệt hại tài | 0.6305 [SOURCE_4] ILO-VCCI_Labour-Law-Guide-Book-V04-Final | tr.10 | CHƯƠNG I. QUAN HỆ LAO ĐỘNG VÀ HỢP ĐỒNG LAO ĐỘNG > I. QUAN HỆ | 0.5306 [SOURCE_5] giao trinh Luat lao dong CB 2005 (1) | tr.95 | IV. TRÁCH NHIỆM VẬT CHẤT TRONG QUAN HỆ LAO ĐỘNG > 1. Khái ni | 0.422 | R16: GeminiProvider | S16: 20.5 | T16: 1 | U16: 0.92307692 | V16: Yes | W16: Yes | X16: PASS | AA16: =IF(Z16="",X16,Z16)
A17: LAW_A_016 | B17: Scenario-based | C17: Một người tìm việc thông qua trung tâm dịch vụ việc làm. Theo giáo trình, quan hệ này có nằm trong đối tượng điều chỉnh của Luật lao động không? | D17: Có. Đây là một dạng quan hệ về việc làm giữa NLĐ và trung tâm dịch vụ việc làm, được xếp vào các quan hệ liên quan đến quan hệ lao động. | E17: Căn cứ: phần “Bài 1 - Quan hệ việc làm”, trang 5. Nội dung được tài liệu xác nhận: Có. Đây là một dạng quan hệ về việc làm giữa NLĐ và trung tâm dịch vụ việc làm, được xếp vào các quan hệ liên quan đến quan hệ lao động. | F17: 5 | G17: Bài 1 - Quan hệ việc làm | H17: NLĐ | trung tâm dịch vụ việc làm | quan hệ việc làm | I17: Hard | J17: Single Chunk | K17: Yes | L17: Answer from document | N17: giao trinh Luat lao dong CB 2005 (1) | O17: Dựa trên tài liệu được cung cấp, tôi không tìm thấy thông tin để trả lời câu hỏi này. | Q17: [SOURCE_1] giao trinh Luat lao dong CB 2005 (1) | tr.3 | BÀI 1 > KHÁI NIỆM LUẬT LAO ĐỘNG VIỆT NAM > I - ĐỐI TƯỢNG VÀ | 0.9622 [SOURCE_2] giao trinh Luat lao dong CB 2005 (1) | tr.3 | a - Quan hệ lao động | 0.6522 [SOURCE_3] luu-ban-nhap-tu-dong-3-4 | tr.73 | Điều 10. Quyền làm việc của người lao động | 0.5572 | R17: GeminiProvider | S17: 24.5 | T17: 0 | U17: 0 | V17: No | W17: No | X17: FAIL | Y17: Từ chối trả lời dù câu hỏi có đáp án | AA17: =IF(Z17="",X17,Z17)
A18: LAW_A_017 | B18: Multi-hop | C18: Từ cách giáo trình xác định đối tượng và phương pháp điều chỉnh, hãy giải thích vì sao HĐLĐ vừa mang tính thỏa thuận vừa chịu giới hạn pháp luật. | D18: Các bên tự do, bình đẳng, tự nguyện thỏa thuận về quá trình lao động, nhưng pháp luật đặt ra khung/chuẩn mực, trong đó quyền lợi thường được ấn định mức tối thiểu và nghĩa vụ ở mức tối đa để bảo vệ quan hệ lao động. | E18: Căn cứ: phần “Bài 1 - Đối tượng & phương pháp”, trang 4. Nội dung được tài liệu xác nhận: Các bên tự do, bình đẳng, tự nguyện thỏa thuận về quá trình lao động, nhưng pháp luật đặt ra khung/chuẩn mực, trong đó quyền lợi thường được ấn định mức tối thiểu và nghĩa vụ ở mức tối đa để bảo vệ quan hệ lao động. | F18: 4 | G18: Bài 1 - Đối tượng & phương pháp | H18: tự do thỏa thuận | khung pháp lý | quyền tối thiểu | nghĩa vụ tối đa | I18: Hard | J18: Multiple Chunks | K18: Yes | L18: Answer from document | N18: giao trinh Luat lao dong CB 2005 (1) | O18: Dựa trên tài liệu được cung cấp, HĐLĐ (hay quan hệ lao động) vừa mang tính thỏa thuận vừa chịu giới hạn pháp luật vì những lý do sau: * **Mang tính thỏa thuận:** Trong Luật lao động, phương pháp thỏa thuận cho phép hai bên cùng nhau thỏa thuận các vấn đề liên quan trong quá trình lao động trên cơ sở tự nguyện, bình đẳng nhằm bảo đảm cho hai bên cùng có lợi [SOURCE | Q18: [SOURCE_1] giao trinh Luat lao dong CB 2005 (1) | tr.7 | a - Phương pháp thỏa thuận | 0.5369 [SOURCE_2] giao trinh Luat lao dong CB 2005 (1) | tr.7 | 2 - Phương pháp điều chỉnh của luật lao động | 0.4546 [SOURCE_3] giao trinh Luat lao dong CB 2005 (1) | tr.182 | 5. Đặc điểm và phân loại thẩm quyền của công đoàn > a. Đặc đ | 0.4193 | R18: GeminiProvider | S18: 21.1 | T18: 0 | U18: 0.53846154 | V18: No | W18: No | X18: PARTIAL | Y18: Thiếu từ khóa (0%); Không trích tài liệu mong đợi (có trong ngữ cảnh); Không trích đúng trang 4 (±1) | AA18: =IF(Z18="",X18,Z18)
A19: LAW_A_018 | B19: Multi-hop | C19: Giáo trình liên hệ quan hệ tranh chấp lao động và đình công với mục tiêu ổn định quan hệ lao động như thế nào? | D19: Việc giải quyết tranh chấp/đình công do các cơ quan, tổ chức có thẩm quyền thực hiện nhằm bảo đảm quyền lợi các bên và duy trì sự hài hòa, ổn định của quan hệ lao động. | E19: Căn cứ: phần “Bài 1 - Tranh chấp lao động”, trang 7. Nội dung được tài liệu xác nhận: Việc giải quyết tranh chấp/đình công do các cơ quan, tổ chức có thẩm quyền thực hiện nhằm bảo đảm quyền lợi các bên và duy trì sự hài hòa, ổn định của quan hệ lao động. | F19: 7 | G19: Bài 1 - Tranh chấp lao động | H19: tranh chấp | đình công | cơ quan thẩm quyền | hài hòa | ổn định | I19: Hard | J19: Single Chunk | K19: Yes | L19: Answer from document | N19: giao trinh Luat lao dong CB 2005 (1) | W19: n/a | X19: BLOCKED | Y19: Lỗi API: HTTP 500: {"detail":"RAG Chat lỗi: Gemini API đã vượt quota/rate limit. Chi tiết: 429 RESOURCE_EXHAUSTED. {'error': {'code': 429, 'message': 'You exceeded your current quota, please check your plan and billing details. For more information on this error, head to: https://ai.google.dev/gemini-api/docs/rate-limits. To monitor your current usage, head to: https://ai.dev/rate-limit. \\n* Quota exceeded for metric: generativelanguage.googleapis.com/generate_content_free_tier_requests, limit: 20, model: gemini- | AA19: =IF(Z19="",X19,Z19)
A20: LAW_A_019 | B20: Source-awareness | C20: Nếu hỏi “quy định hiện hành năm 2026 về làm thêm giờ”, RAG có nên chỉ dùng con số trong giáo trình 2005 không? | D20: Không nên. Giáo trình là nguồn lịch sử/giảng dạy cũ; hệ thống phải nhận diện thời điểm của nguồn và không trình bày quy định trong tài liệu này như pháp luật hiện hành năm 2026 nếu không có nguồn cập nhật. | E20: Căn cứ: phần “Lưu ý nguồn/tính thời điểm”, trang 1. Nội dung được tài liệu xác nhận: Không nên. Giáo trình là nguồn lịch sử/giảng dạy cũ; hệ thống phải nhận diện thời điểm của nguồn và không trình bày quy định trong tài liệu này như pháp luật hiện hành năm 2026 nếu không có nguồn cập nhật. | F20: 1 | G20: Lưu ý nguồn/tính thời điểm | H20: nguồn 2005 | lịch sử | không suy diễn hiện hành | I20: Hard | J20: Multiple Chunks | K20: Yes | L20: Answer with temporal caveat | M20: Tests temporal grounding. | N20: giao trinh Luat lao dong CB 2005 (1) | O20: Dựa trên tài liệu được cung cấp, tôi không tìm thấy thông tin để trả lời câu hỏi này. | R20: (no LLM call: early exit) | S20: 17.8 | T20: 0 | U20: 0 | V20: No | W20: No | X20: FAIL | Y20: Từ chối trả lời dù câu hỏi có đáp án | AA20: =IF(Z20="",X20,Z20)
A21: LAW_A_020 | B21: Synthesis | C21: Theo giáo trình, vì sao Luật lao động không chỉ điều chỉnh việc “đi làm nhận lương” mà còn bao phủ nhiều quan hệ khác? | D21: Vì ngoài quan hệ lao động làm công ăn lương, quá trình sử dụng lao động còn phát sinh các quan hệ gắn chặt như việc làm, học nghề, bồi thường, BHXH, công đoàn, tranh chấp/đình công và quản lý lao động; các quan hệ này cần được điều chỉnh để quan hệ lao động vận hành ổn định. | E21: Căn cứ: phần “Bài 1 - Tổng hợp” Nội dung được tài liệu xác nhận: Vì ngoài quan hệ lao động làm công ăn lương, quá trình sử dụng lao động còn phát sinh các quan hệ gắn chặt như việc làm, học nghề, bồi thường, BHXH, công đoàn, tranh chấp/đình công và quản lý lao động; các quan hệ này cần được điều chỉnh để quan hệ lao động vận hành ổn định. | G21: Bài 1 - Tổng hợp | H21: quan hệ lao động | quan hệ liên quan | ổn định | I21: Hard | J21: Multiple Chunks | K21: Yes | L21: Answer from document | N21: giao trinh Luat lao dong CB 2005 (1) | W21: n/a | X21: BLOCKED | Y21: Lỗi API: chưa chạy | AA21: =IF(Z21="",X21,Z21)
A22: LAW_B_001 | B22: Direct Fact | C22: Theo sổ tay, hợp đồng lao động có thể được giao kết bằng lời nói trong trường hợp nào? | D22: Theo tài liệu, giao kết bằng lời nói áp dụng với công việc tạm thời có thời hạn dưới 03 tháng. | E22: Căn cứ: phần “Phần I - Hợp đồng lao động”, trang 11. Nội dung được tài liệu xác nhận: Theo tài liệu, giao kết bằng lời nói áp dụng với công việc tạm thời có thời hạn dưới 03 tháng. | F22: 11 | G22: Phần I - Hợp đồng lao động | H22: lời nói | tạm thời | dưới 03 tháng | I22: Easy | J22: Single Chunk | K22: Yes | L22: Answer from document | N22: so-tay-kien-thuc-phap-luat-lao-dong-cdi | W22: n/a | X22: BLOCKED | Y22: Lỗi API: chưa chạy | AA22: =IF(Z22="",X22,Z22)
A23: LAW_B_002 | B23: Concept | C23: Vì sao sổ tay khuyến nghị nên ký hợp đồng lao động? | D23: Vì hợp đồng thể hiện thỏa thuận về công việc, lương, điều kiện làm việc, quyền và nghĩa vụ và là căn cứ xem xét khi phát sinh tranh chấp. | E23: Căn cứ: phần “Phần I - Hợp đồng lao động” Nội dung được tài liệu xác nhận: Vì hợp đồng thể hiện thỏa thuận về công việc, lương, điều kiện làm việc, quyền và nghĩa vụ và là căn cứ xem xét khi phát sinh tranh chấp. | G23: Phần I - Hợp đồng lao động | H23: thỏa thuận | căn cứ | tranh chấp | I23: Easy | J23: Single Chunk | K23: Yes | L23: Answer from document | N23: so-tay-kien-thuc-phap-luat-lao-dong-cdi | W23: n/a | X23: BLOCKED | Y23: Lỗi API: chưa chạy | AA23: =IF(Z23="",X23,Z23)
A24: LAW_B_003 | B24: Direct Fact | C24: Sổ tay có đề cập nội dung “khi nào được ký HĐLĐ không xác định thời hạn” ở phần nào? | D24: Nội dung này nằm trong Phần I - Hợp đồng lao động. | E24: Căn cứ: phần “Phần I - Hợp đồng lao động”, trang 6. Nội dung được tài liệu xác nhận: Nội dung này nằm trong Phần I - Hợp đồng lao động. | F24: 6 | G24: Phần I - Hợp đồng lao động | H24: HĐLĐ không xác định thời hạn | I24: Easy | J24: Single Chunk | K24: Yes | L24: Answer from document | N24: so-tay-kien-thuc-phap-luat-lao-dong-cdi | W24: n/a | X24: BLOCKED | Y24: Lỗi API: chưa chạy | AA24: =IF(Z24="",X24,Z24)
A25: LAW_B_004 | B25: Direct Fact | C25: Sổ tay xếp quy định về thử việc vào nhóm nội dung nào? | D25: Thuộc Phần I - Hợp đồng lao động. | E25: Căn cứ: phần “Phần I - Hợp đồng lao động”, trang 6. Nội dung được tài liệu xác nhận: Thuộc Phần I - Hợp đồng lao động. | F25: 6 | G25: Phần I - Hợp đồng lao động | H25: thử việc | hợp đồng lao động | I25: Easy | J25: Single Chunk | K25: Yes | L25: Answer from document | N25: so-tay-kien-thuc-phap-luat-lao-dong-cdi | W25: n/a | X25: BLOCKED | Y25: Lỗi API: chưa chạy | AA25: =IF(Z25="",X25,Z25)
A26: LAW_B_005 | B26: Direct Fact | C26: Sổ tay xếp trả tiền lương làm thêm giờ vào phần nào? | D26: Thuộc Phần II - Tiền lương. | E26: Căn cứ: phần “Phần II - Tiền lương”, trang 6. Nội dung được tài liệu xác nhận: Thuộc Phần II - Tiền lương. | F26: 6 | G26: Phần II - Tiền lương | H26: làm thêm giờ | tiền lương | I26: Easy | J26: Single Chunk | K26: Yes | L26: Answer from document | N26: so-tay-kien-thuc-phap-luat-lao-dong-cdi | W26: n/a | X26: BLOCKED | Y26: Lỗi API: chưa chạy | AA26: =IF(Z26="",X26,Z26)
A27: LAW_B_006 | B27: Direct Fact | C27: Sổ tay xếp nghỉ giữa giờ, nghỉ phép và nghỉ việc riêng vào phần nào? | D27: Thuộc Phần III - Thời gian làm việc và nghỉ ngơi. | E27: Căn cứ: phần “Phần III - Thời gian làm việc và nghỉ ngơi”, trang 6. Nội dung được tài liệu xác nhận: Thuộc Phần III - Thời gian làm việc và nghỉ ngơi. | F27: 6 | G27: Phần III - Thời gian làm việc và nghỉ ngơi | H27: nghỉ giữa giờ | nghỉ phép | nghỉ việc riêng | I27: Easy | J27: Single Chunk | K27: Yes | L27: Answer from document | N27: so-tay-kien-thuc-phap-luat-lao-dong-cdi | W27: n/a | X27: BLOCKED | Y27: Lỗi API: chưa chạy | AA27: =IF(Z27="",X27,Z27)
A28: LAW_B_007 | B28: Direct Fact | C28: Sổ tay xếp tai nạn lao động và bệnh nghề nghiệp vào phần nào? | D28: Thuộc Phần IV - An toàn lao động. | E28: Căn cứ: phần “Phần IV - An toàn lao động”, trang 6. Nội dung được tài liệu xác nhận: Thuộc Phần IV - An toàn lao động. | F28: 6 | G28: Phần IV - An toàn lao động | H28: an toàn lao động | tai nạn | bệnh nghề nghiệp | I28: Easy | J28: Single Chunk | K28: Yes | L28: Answer from document | N28: so-tay-kien-thuc-phap-luat-lao-dong-cdi | W28: n/a | X28: BLOCKED | Y28: Lỗi API: chưa chạy | AA28: =IF(Z28="",X28,Z28)
A29: LAW_B_008 | B29: Scenario-based | C29: Một người làm việc tạm thời 2 tháng, hai bên chỉ thỏa thuận miệng về lương và an toàn lao động. Theo tình huống trong sổ tay, có được coi là đã giao kết HĐLĐ không? | D29: Có. Tài liệu kết luận trường hợp làm tạm thời 2 tháng thuộc trường hợp có thể giao kết bằng lời nói theo quy định mà sổ tay viện dẫn. | E29: Căn cứ: phần “Phần I - Hợp đồng lao động” Nội dung được tài liệu xác nhận: Có. Tài liệu kết luận trường hợp làm tạm thời 2 tháng thuộc trường hợp có thể giao kết bằng lời nói theo quy định mà sổ tay viện dẫn. | G29: Phần I - Hợp đồng lao động | H29: 2 tháng | lời nói | giao kết HĐLĐ | I29: Medium | J29: Single Chunk | K29: Yes | L29: Answer from document | N29: so-tay-kien-thuc-phap-luat-lao-dong-cdi | W29: n/a | X29: BLOCKED | Y29: Lỗi API: chưa chạy | AA29: =IF(Z29="",X29,Z29)
A30: LAW_B_009 | B30: Concept | C30: Hợp đồng lao động có ý nghĩa gì khi xảy ra tranh chấp theo sổ tay? | D30: Là căn cứ thể hiện các thỏa thuận của các bên để xem xét quyền, nghĩa vụ và giải quyết tranh chấp. | E30: Căn cứ: phần “Phần I - Hợp đồng lao động” Nội dung được tài liệu xác nhận: Là căn cứ thể hiện các thỏa thuận của các bên để xem xét quyền, nghĩa vụ và giải quyết tranh chấp. | G30: Phần I - Hợp đồng lao động | H30: căn cứ | quyền nghĩa vụ | tranh chấp | I30: Medium | J30: Single Chunk | K30: Yes | L30: Answer from document | N30: so-tay-kien-thuc-phap-luat-lao-dong-cdi | W30: n/a | X30: BLOCKED | Y30: Lỗi API: chưa chạy | AA30: =IF(Z30="",X30,Z30)
A31: LAW_B_010 | B31: Navigation | C31: Muốn tìm câu trả lời về việc công ty có được giữ văn bằng gốc của NLĐ hay không, cần truy xuất phần nào của sổ tay? | D31: Phần VIII - Khiếu nại, khiếu kiện về lao động. | E31: Căn cứ: phần “Phần VIII - Khiếu nại, khiếu kiện”, trang 7. Nội dung được tài liệu xác nhận: Phần VIII - Khiếu nại, khiếu kiện về lao động. | F31: 7 | G31: Phần VIII - Khiếu nại, khiếu kiện | H31: văn bằng gốc | khiếu nại | khiếu kiện | I31: Medium | J31: Single Chunk | K31: Yes | L31: Answer from document | N31: so-tay-kien-thuc-phap-luat-lao-dong-cdi | W31: n/a | X31: BLOCKED | Y31: Lỗi API: chưa chạy | AA31: =IF(Z31="",X31,Z31)
A32: LAW_B_011 | B32: Navigation | C32: Muốn tìm quy trình tiến hành đình công và tiền lương trong ngày đình công, cần truy xuất phần nào? | D32: Phần VII - Đình công. | E32: Căn cứ: phần “Phần VII - Đình công”, trang 7. Nội dung được tài liệu xác nhận: Phần VII - Đình công. | F32: 7 | G32: Phần VII - Đình công | H32: đình công | trình tự | tiền lương | I32: Medium | J32: Single Chunk | K32: Yes | L32: Answer from document | N32: so-tay-kien-thuc-phap-luat-lao-dong-cdi | W32: n/a | X32: BLOCKED | Y32: Lỗi API: chưa chạy | AA32: =IF(Z32="",X32,Z32)
A33: LAW_B_012 | B33: Navigation | C33: Câu hỏi về quyền lợi của phụ nữ mang thai và chế độ nghỉ thai sản nằm ở phần nào? | D33: Phần VI - Chế độ đối với lao động nữ. | E33: Căn cứ: phần “Phần VI - Lao động nữ”, trang 7. Nội dung được tài liệu xác nhận: Phần VI - Chế độ đối với lao động nữ. | F33: 7 | G33: Phần VI - Lao động nữ | H33: mang thai | thai sản | lao động nữ | I33: Medium | J33: Single Chunk | K33: Yes | L33: Answer from document | N33: so-tay-kien-thuc-phap-luat-lao-dong-cdi | W33: n/a | X33: BLOCKED | Y33: Lỗi API: chưa chạy | AA33: =IF(Z33="",X33,Z33)
A34: LAW_B_013 | B34: Navigation | C34: Câu hỏi về sa thải trái pháp luật và trách nhiệm của NSDLĐ khi sa thải trái pháp luật nằm ở đâu? | D34: Phần V - Kỷ luật lao động. | E34: Căn cứ: phần “Phần V - Kỷ luật lao động”, trang 7. Nội dung được tài liệu xác nhận: Phần V - Kỷ luật lao động. | F34: 7 | G34: Phần V - Kỷ luật lao động | H34: sa thải trái pháp luật | trách nhiệm NSDLĐ | I34: Medium | J34: Single Chunk | K34: Yes | L34: Answer from document | N34: so-tay-kien-thuc-phap-luat-lao-dong-cdi | W34: n/a | X34: BLOCKED | Y34: Lỗi API: chưa chạy | AA34: =IF(Z34="",X34,Z34)
A35: LAW_B_014 | B35: Navigation | C35: Nếu NLĐ làm mất tài sản của doanh nghiệp, sổ tay định hướng tra cứu nội dung nào? | D35: Tra cứu câu hỏi “Bồi thường thiệt hại do làm mất tài sản?” trong Phần V - Kỷ luật lao động. | E35: Căn cứ: phần “Phần V - Kỷ luật lao động”, trang 7. Nội dung được tài liệu xác nhận: Tra cứu câu hỏi “Bồi thường thiệt hại do làm mất tài sản?” trong Phần V - Kỷ luật lao động. | F35: 7 | G35: Phần V - Kỷ luật lao động | H35: bồi thường | mất tài sản | kỷ luật | I35: Medium | J35: Single Chunk | K35: Yes | L35: Answer from document | N35: so-tay-kien-thuc-phap-luat-lao-dong-cdi | W35: n/a | X35: BLOCKED | Y35: Lỗi API: chưa chạy | AA35: =IF(Z35="",X35,Z35)
A36: LAW_B_015 | B36: Multi-hop | C36: Một NLĐ vừa hỏi về nghỉ phép vừa hỏi về lương làm thêm giờ. RAG cần lấy tối thiểu từ những phần nào của sổ tay? | D36: Ít nhất từ Phần II - Tiền lương (lương làm thêm giờ) và Phần III - Thời gian làm việc và nghỉ ngơi (nghỉ phép). | E36: Căn cứ: phần “Phần II + III”, trang 6. Nội dung được tài liệu xác nhận: Ít nhất từ Phần II - Tiền lương (lương làm thêm giờ) và Phần III - Thời gian làm việc và nghỉ ngơi (nghỉ phép). | F36: 6 | G36: Phần II + III | H36: tiền lương | làm thêm | nghỉ phép | I36: Hard | J36: Multiple Chunks | K36: Yes | L36: Answer from document | N36: so-tay-kien-thuc-phap-luat-lao-dong-cdi | W36: n/a | X36: BLOCKED | Y36: Lỗi API: chưa chạy | AA36: =IF(Z36="",X36,Z36)
A37: LAW_B_016 | B37: Multi-hop | C37: Một vụ việc có tai nạn lao động và sau đó phát sinh khiếu kiện. Để trả lời theo cấu trúc sổ tay, cần kết hợp những phần nào? | D37: Cần kết hợp Phần IV - An toàn lao động với Phần VIII - Khiếu nại, khiếu kiện về lao động. | E37: Căn cứ: phần “Phần IV + VIII”, trang 6. Nội dung được tài liệu xác nhận: Cần kết hợp Phần IV - An toàn lao động với Phần VIII - Khiếu nại, khiếu kiện về lao động. | F37: 6 | G37: Phần IV + VIII | H37: tai nạn lao động | khiếu nại | khiếu kiện | I37: Hard | J37: Multiple Chunks | K37: Yes | L37: Answer from document | N37: so-tay-kien-thuc-phap-luat-lao-dong-cdi | W37: n/a | X37: BLOCKED | Y37: Lỗi API: chưa chạy | AA37: =IF(Z37="",X37,Z37)
A38: LAW_B_017 | B38: False Premise | C38: “Mọi hợp đồng lao động đều bắt buộc phải lập thành văn bản” có phù hợp với nội dung sổ tay không? | D38: Không. Sổ tay nêu hai hình thức là văn bản và lời nói, trong đó lời nói được áp dụng cho công việc tạm thời dưới 03 tháng theo quy định mà tài liệu viện dẫn. | E38: Căn cứ: phần “Phần I - Hợp đồng lao động”, trang None. Nội dung được tài liệu xác nhận: Không. Sổ tay nêu hai hình thức là văn bản và lời nói, trong đó lời nói được áp dụng cho công việc tạm thời dưới 03 tháng theo quy định mà tài liệu viện dẫn. | G38: Phần I - Hợp đồng lao động | H38: văn bản | lời nói | dưới 03 tháng | I38: Hard | J38: Single Chunk | K38: Yes | L38: Answer from document | N38: so-tay-kien-thuc-phap-luat-lao-dong-cdi | W38: n/a | X38: BLOCKED | Y38: Lỗi API: chưa chạy | AA38: =IF(Z38="",X38,Z38)
A39: LAW_B_018 | B39: Source-awareness | C39: Nếu người dùng hỏi pháp luật hiện hành 2026, RAG có nên trả lời trực tiếp theo ngưỡng “dưới 03 tháng” của sổ tay không? | D39: Không nên coi đó là quy định hiện hành chỉ dựa vào sổ tay này. Cần nêu đây là nội dung của tài liệu và ưu tiên/đối chiếu nguồn pháp luật cập nhật hơn nếu câu hỏi yêu cầu hiện hành. | E39: Căn cứ: phần “Phần I - Hợp đồng lao động”, trang 11. Nội dung được tài liệu xác nhận: Không nên coi đó là quy định hiện hành chỉ dựa vào sổ tay này. Cần nêu đây là nội dung của tài liệu và ưu tiên/đối chiếu nguồn pháp luật cập nhật hơn nếu câu hỏi yêu cầu hiện hành. | F39: 11 | G39: Phần I - Hợp đồng lao động | H39: nguồn cũ | thời điểm | quy định hiện hành | I39: Hard | J39: Multiple Chunks | K39: Yes | L39: Answer with temporal caveat | M39: Tests outdated-source handling. | N39: so-tay-kien-thuc-phap-luat-lao-dong-cdi | W39: n/a | X39: BLOCKED | Y39: Lỗi API: chưa chạy | AA39: =IF(Z39="",X39,Z39)
A40: LAW_B_019 | B40: Synthesis | C40: Sổ tay được thiết kế theo hình thức nào và điều đó có ý nghĩa gì cho RAG? | D40: Tài liệu được thiết kế dạng Hỏi - Đáp, với thông tin và giải thích ngắn gọn; các câu hỏi dựa trên tình huống thực tế. Với RAG, cấu trúc này phù hợp cho truy xuất theo câu hỏi/tình huống nhưng vẫn cần giữ đúng bối cảnh và thời điểm của nguồn. | E40: Căn cứ: phần “Giới thiệu”, trang 5. Nội dung được tài liệu xác nhận: Tài liệu được thiết kế dạng Hỏi - Đáp, với thông tin và giải thích ngắn gọn; các câu hỏi dựa trên tình huống thực tế. Với RAG, cấu trúc này phù hợp cho truy xuất theo câu hỏi/tình huống nhưng vẫn cần giữ đúng bối cảnh và thời điểm của nguồn. | F40: 5 | G40: Giới thiệu | H40: Hỏi-Đáp | tình huống thực tế | ngắn gọn | I40: Hard | J40: Single Chunk | K40: Yes | L40: Answer from document | N40: so-tay-kien-thuc-phap-luat-lao-dong-cdi | W40: n/a | X40: BLOCKED | Y40: Lỗi API: chưa chạy | AA40: =IF(Z40="",X40,Z40)
...

Sheet Retrieval
A1: ID | B1: Document | C1: Category | D1: Difficulty | E1: Doc@1 | F1: Doc@5 | G1: Page@5 (±1) | H1: Keyword coverage (top 5) | I1: Best rerank | J1: Refused (< threshold) | K1: Top sources
