Workbook

Sheet Summary
A1: TC_LuatLD — Test Summary
A2: Effective Status = Final Status (tester) nếu đã điền, nếu không = Suggested Status (tự động).
A4: Status | B4: Count | C4: Rate
A5: PASS | B5: =COUNTIF(Results!$AA$2:$AA$101,"PASS") | C5: =B5/100
A6: PARTIAL | B6: =COUNTIF(Results!$AA$2:$AA$101,"PARTIAL") | C6: =B6/100
A7: FAIL | B7: =COUNTIF(Results!$AA$2:$AA$101,"FAIL") | C7: =B7/100
A8: BLOCKED | B8: =COUNTIF(Results!$AA$2:$AA$101,"BLOCKED") | C8: =B8/100
A9: Total | B9: =SUM(B5:B8)
A10: Reviewed by tester | B10: =COUNTA(Results!Z2:Z101)
A11: Median latency (s) | B11: 18.1
A13: Theo tài liệu
A14: Document | B14: Total | C14: PASS | D14: PARTIAL | E14: FAIL | F14: BLOCKED | G14: Pass rate
A15: giao trinh Luat lao dong CB 2005 (1) | B15: =COUNTIF(Results!$N$2:$N$101,A15) | C15: =COUNTIFS(Results!$N$2:$N$101,A15,Results!$AA$2:$AA$101,"PASS") | D15: =COUNTIFS(Results!$N$2:$N$101,A15,Results!$AA$2:$AA$101,"PARTIAL") | E15: =COUNTIFS(Results!$N$2:$N$101,A15,Results!$AA$2:$AA$101,"FAIL") | F15: =COUNTIFS(Results!$N$2:$N$101,A15,Results!$AA$2:$AA$101,"BLOCKED") | G15: =IF(B15=0,0,C15/B15)
A16: so-tay-kien-thuc-phap-luat-lao-dong-cdi | B16: =COUNTIF(Results!$N$2:$N$101,A16) | C16: =COUNTIFS(Results!$N$2:$N$101,A16,Results!$AA$2:$AA$101,"PASS") | D16: =COUNTIFS(Results!$N$2:$N$101,A16,Results!$AA$2:$AA$101,"PARTIAL") | E16: =COUNTIFS(Results!$N$2:$N$101,A16,Results!$AA$2:$AA$101,"FAIL") | F16: =COUNTIFS(Results!$N$2:$N$101,A16,Results!$AA$2:$AA$101,"BLOCKED") | G16: =IF(B16=0,0,C16/B16)
A17: luu-ban-nhap-tu-dong-3-4 | B17: =COUNTIF(Results!$N$2:$N$101,A17) | C17: =COUNTIFS(Results!$N$2:$N$101,A17,Results!$AA$2:$AA$101,"PASS") | D17: =COUNTIFS(Results!$N$2:$N$101,A17,Results!$AA$2:$AA$101,"PARTIAL") | E17: =COUNTIFS(Results!$N$2:$N$101,A17,Results!$AA$2:$AA$101,"FAIL") | F17: =COUNTIFS(Results!$N$2:$N$101,A17,Results!$AA$2:$AA$101,"BLOCKED") | G17: =IF(B17=0,0,C17/B17)
A18: ILO-VCCI_Labour-Law-Guide-Book-V04-Final | B18: =COUNTIF(Results!$N$2:$N$101,A18) | C18: =COUNTIFS(Results!$N$2:$N$101,A18,Results!$AA$2:$AA$101,"PASS") | D18: =COUNTIFS(Results!$N$2:$N$101,A18,Results!$AA$2:$AA$101,"PARTIAL") | E18: =COUNTIFS(Results!$N$2:$N$101,A18,Results!$AA$2:$AA$101,"FAIL") | F18: =COUNTIFS(Results!$N$2:$N$101,A18,Results!$AA$2:$AA$101,"BLOCKED") | G18: =IF(B18=0,0,C18/B18)
A19: Văn-bản-hợp-nhất-18-VBHN-VPQH | B19: =COUNTIF(Results!$N$2:$N$101,A19) | C19: =COUNTIFS(Results!$N$2:$N$101,A19,Results!$AA$2:$AA$101,"PASS") | D19: =COUNTIFS(Results!$N$2:$N$101,A19,Results!$AA$2:$AA$101,"PARTIAL") | E19: =COUNTIFS(Results!$N$2:$N$101,A19,Results!$AA$2:$AA$101,"FAIL") | F19: =COUNTIFS(Results!$N$2:$N$101,A19,Results!$AA$2:$AA$101,"BLOCKED") | G19: =IF(B19=0,0,C19/B19)
A21: Theo độ khó
A22: Retrieval Difficulty | B22: Total | C22: PASS | D22: PARTIAL | E22: FAIL | F22: BLOCKED | G22: Pass rate
A23: Easy | B23: =COUNTIF(Results!$I$2:$I$101,A23) | C23: =COUNTIFS(Results!$I$2:$I$101,A23,Results!$AA$2:$AA$101,"PASS") | D23: =COUNTIFS(Results!$I$2:$I$101,A23,Results!$AA$2:$AA$101,"PARTIAL") | E23: =COUNTIFS(Results!$I$2:$I$101,A23,Results!$AA$2:$AA$101,"FAIL") | F23: =COUNTIFS(Results!$I$2:$I$101,A23,Results!$AA$2:$AA$101,"BLOCKED") | G23: =IF(B23=0,0,C23/B23)
A24: Medium | B24: =COUNTIF(Results!$I$2:$I$101,A24) | C24: =COUNTIFS(Results!$I$2:$I$101,A24,Results!$AA$2:$AA$101,"PASS") | D24: =COUNTIFS(Results!$I$2:$I$101,A24,Results!$AA$2:$AA$101,"PARTIAL") | E24: =COUNTIFS(Results!$I$2:$I$101,A24,Results!$AA$2:$AA$101,"FAIL") | F24: =COUNTIFS(Results!$I$2:$I$101,A24,Results!$AA$2:$AA$101,"BLOCKED") | G24: =IF(B24=0,0,C24/B24)
A25: Hard | B25: =COUNTIF(Results!$I$2:$I$101,A25) | C25: =COUNTIFS(Results!$I$2:$I$101,A25,Results!$AA$2:$AA$101,"PASS") | D25: =COUNTIFS(Results!$I$2:$I$101,A25,Results!$AA$2:$AA$101,"PARTIAL") | E25: =COUNTIFS(Results!$I$2:$I$101,A25,Results!$AA$2:$AA$101,"FAIL") | F25: =COUNTIFS(Results!$I$2:$I$101,A25,Results!$AA$2:$AA$101,"BLOCKED") | G25: =IF(B25=0,0,C25/B25)
A27: Theo loại câu hỏi
A28: Category | B28: Total | C28: PASS | D28: PARTIAL | E28: FAIL | F28: BLOCKED | G28: Pass rate
A29: Definition | B29: =COUNTIF(Results!$B$2:$B$101,A29) | C29: =COUNTIFS(Results!$B$2:$B$101,A29,Results!$AA$2:$AA$101,"PASS") | D29: =COUNTIFS(Results!$B$2:$B$101,A29,Results!$AA$2:$AA$101,"PARTIAL") | E29: =COUNTIFS(Results!$B$2:$B$101,A29,Results!$AA$2:$AA$101,"FAIL") | F29: =COUNTIFS(Results!$B$2:$B$101,A29,Results!$AA$2:$AA$101,"BLOCKED") | G29: =IF(B29=0,0,C29/B29)
A30: List | B30: =COUNTIF(Results!$B$2:$B$101,A30) | C30: =COUNTIFS(Results!$B$2:$B$101,A30,Results!$AA$2:$AA$101,"PASS") | D30: =COUNTIFS(Results!$B$2:$B$101,A30,Results!$AA$2:$AA$101,"PARTIAL") | E30: =COUNTIFS(Results!$B$2:$B$101,A30,Results!$AA$2:$AA$101,"FAIL") | F30: =COUNTIFS(Results!$B$2:$B$101,A30,Results!$AA$2:$AA$101,"BLOCKED") | G30: =IF(B30=0,0,C30/B30)
A31: Direct Fact | B31: =COUNTIF(Results!$B$2:$B$101,A31) | C31: =COUNTIFS(Results!$B$2:$B$101,A31,Results!$AA$2:$AA$101,"PASS") | D31: =COUNTIFS(Results!$B$2:$B$101,A31,Results!$AA$2:$AA$101,"PARTIAL") | E31: =COUNTIFS(Results!$B$2:$B$101,A31,Results!$AA$2:$AA$101,"FAIL") | F31: =COUNTIFS(Results!$B$2:$B$101,A31,Results!$AA$2:$AA$101,"BLOCKED") | G31: =IF(B31=0,0,C31/B31)
A32: Concept | B32: =COUNTIF(Results!$B$2:$B$101,A32) | C32: =COUNTIFS(Results!$B$2:$B$101,A32,Results!$AA$2:$AA$101,"PASS") | D32: =COUNTIFS(Results!$B$2:$B$101,A32,Results!$AA$2:$AA$101,"PARTIAL") | E32: =COUNTIFS(Results!$B$2:$B$101,A32,Results!$AA$2:$AA$101,"FAIL") | F32: =COUNTIFS(Results!$B$2:$B$101,A32,Results!$AA$2:$AA$101,"BLOCKED") | G32: =IF(B32=0,0,C32/B32)
A33: Rule | B33: =COUNTIF(Results!$B$2:$B$101,A33) | C33: =COUNTIFS(Results!$B$2:$B$101,A33,Results!$AA$2:$AA$101,"PASS") | D33: =COUNTIFS(Results!$B$2:$B$101,A33,Results!$AA$2:$AA$101,"PARTIAL") | E33: =COUNTIFS(Results!$B$2:$B$101,A33,Results!$AA$2:$AA$101,"FAIL") | F33: =COUNTIFS(Results!$B$2:$B$101,A33,Results!$AA$2:$AA$101,"BLOCKED") | G33: =IF(B33=0,0,C33/B33)
A34: Comparison | B34: =COUNTIF(Results!$B$2:$B$101,A34) | C34: =COUNTIFS(Results!$B$2:$B$101,A34,Results!$AA$2:$AA$101,"PASS") | D34: =COUNTIFS(Results!$B$2:$B$101,A34,Results!$AA$2:$AA$101,"PARTIAL") | E34: =COUNTIFS(Results!$B$2:$B$101,A34,Results!$AA$2:$AA$101,"FAIL") | F34: =COUNTIFS(Results!$B$2:$B$101,A34,Results!$AA$2:$AA$101,"BLOCKED") | G34: =IF(B34=0,0,C34/B34)
A35: Scenario-based | B35: =COUNTIF(Results!$B$2:$B$101,A35) | C35: =COUNTIFS(Results!$B$2:$B$101,A35,Results!$AA$2:$AA$101,"PASS") | D35: =COUNTIFS(Results!$B$2:$B$101,A35,Results!$AA$2:$AA$101,"PARTIAL") | E35: =COUNTIFS(Results!$B$2:$B$101,A35,Results!$AA$2:$AA$101,"FAIL") | F35: =COUNTIFS(Results!$B$2:$B$101,A35,Results!$AA$2:$AA$101,"BLOCKED") | G35: =IF(B35=0,0,C35/B35)
A36: Multi-hop | B36: =COUNTIF(Results!$B$2:$B$101,A36) | C36: =COUNTIFS(Results!$B$2:$B$101,A36,Results!$AA$2:$AA$101,"PASS") | D36: =COUNTIFS(Results!$B$2:$B$101,A36,Results!$AA$2:$AA$101,"PARTIAL") | E36: =COUNTIFS(Results!$B$2:$B$101,A36,Results!$AA$2:$AA$101,"FAIL") | F36: =COUNTIFS(Results!$B$2:$B$101,A36,Results!$AA$2:$AA$101,"BLOCKED") | G36: =IF(B36=0,0,C36/B36)
A37: Source-awareness | B37: =COUNTIF(Results!$B$2:$B$101,A37) | C37: =COUNTIFS(Results!$B$2:$B$101,A37,Results!$AA$2:$AA$101,"PASS") | D37: =COUNTIFS(Results!$B$2:$B$101,A37,Results!$AA$2:$AA$101,"PARTIAL") | E37: =COUNTIFS(Results!$B$2:$B$101,A37,Results!$AA$2:$AA$101,"FAIL") | F37: =COUNTIFS(Results!$B$2:$B$101,A37,Results!$AA$2:$AA$101,"BLOCKED") | G37: =IF(B37=0,0,C37/B37)
A38: Synthesis | B38: =COUNTIF(Results!$B$2:$B$101,A38) | C38: =COUNTIFS(Results!$B$2:$B$101,A38,Results!$AA$2:$AA$101,"PASS") | D38: =COUNTIFS(Results!$B$2:$B$101,A38,Results!$AA$2:$AA$101,"PARTIAL") | E38: =COUNTIFS(Results!$B$2:$B$101,A38,Results!$AA$2:$AA$101,"FAIL") | F38: =COUNTIFS(Results!$B$2:$B$101,A38,Results!$AA$2:$AA$101,"BLOCKED") | G38: =IF(B38=0,0,C38/B38)
A39: Navigation | B39: =COUNTIF(Results!$B$2:$B$101,A39) | C39: =COUNTIFS(Results!$B$2:$B$101,A39,Results!$AA$2:$AA$101,"PASS") | D39: =COUNTIFS(Results!$B$2:$B$101,A39,Results!$AA$2:$AA$101,"PARTIAL") | E39: =COUNTIFS(Results!$B$2:$B$101,A39,Results!$AA$2:$AA$101,"FAIL") | F39: =COUNTIFS(Results!$B$2:$B$101,A39,Results!$AA$2:$AA$101,"BLOCKED") | G39: =IF(B39=0,0,C39/B39)
A40: False Premise | B40: =COUNTIF(Results!$B$2:$B$101,A40) | C40: =COUNTIFS(Results!$B$2:$B$101,A40,Results!$AA$2:$AA$101,"PASS") | D40: =COUNTIFS(Results!$B$2:$B$101,A40,Results!$AA$2:$AA$101,"PARTIAL") | E40: =COUNTIFS(Results!$B$2:$B$101,A40,Results!$AA$2:$AA$101,"FAIL") | F40: =COUNTIFS(Results!$B$2:$B$101,A40,Results!$AA$2:$AA$101,"BLOCKED") | G40: =IF(B40=0,0,C40/B40)
... A45: Procedure | B45: =COUNTIF(Results!$B$2:$B$101,A45) | C45: =COUNTIFS(Results!$B$2:$B$101,A45,Results!$AA$2:$AA$101,"PASS") | D45: =COUNTIFS(Results!$B$2:$B$101,A45,Results!$AA$2:$AA$101,"PARTIAL") | E45: =COUNTIFS(Results!$B$2:$B$101,A45,Results!$AA$2:$AA$101,"FAIL") | F45: =COUNTIFS(Results!$B$2:$B$101,A45,Results!$AA$2:$AA$101,"BLOCKED") | G45: =IF(B45=0,0,C45/B45)

Sheet Results
A1: Test Case ID | B1: Category | C1: Query | D1: Expected Answer | E1: Evidence | F1: Source Page | G1: Source Section | H1: Required Keywords / Key Concepts | I1: Retrieval Difficulty | J1: Expected Retrieval Type | K1: Is Answerable | L1: Expected Behavior | M1: Notes | N1: Document | O1: Actual Answer | P1: Cited Sources | Q1: Context Sources | R1: LLM Model | S1: Latency (s) | T1: Keyword Coverage | U1: Expected-Answer Recall | V1: Cited Expected Doc | W1: Page Match | X1: Suggested Status | Y1: Auto Reasons | Z1: Final Status | AA1: Effective Status | AB1: Defect ID | AC1: Tester Note
A2: LAW_A_001 | B2: Definition | C2: Theo giáo trình, đối tượng điều chỉnh của Luật lao động gồm những nhóm quan hệ nào? | D2: Gồm quan hệ lao động và các quan hệ liên quan chặt chẽ hoặc phát sinh từ quan hệ lao động. | E2: Căn cứ: phần “Bài 1 - Đối tượng điều chỉnh”, trang 3. Nội dung được tài liệu xác nhận: Gồm quan hệ lao động và các quan hệ liên quan chặt chẽ hoặc phát sinh từ quan hệ lao động. | F2: 3 | G2: Bài 1 - Đối tượng điều chỉnh | H2: quan hệ lao động | quan hệ liên quan | I2: Easy | J2: Single Chunk | K2: Yes | L2: Answer from document | N2: giao trinh Luat lao dong CB 2005 (1) | O2: Theo giáo trình, đối tượng điều chỉnh của Luật lao động bao gồm hai nhóm quan hệ xã hội [SOURCE_1]: 1. Quan hệ lao động [SOURCE_1]. 2. Các quan hệ liên quan đến quan hệ lao động (phát sinh trong quá trình sử dụng lao động) [SOURCE_1]. | P2: [SOURCE_1] giao trinh Luat lao dong CB 2005 (1) | tr.3 | BÀI 1 > KHÁI NIỆM LUẬT LAO ĐỘNG VIỆT NAM > I - ĐỐI TƯỢNG VÀ | 0.9984 | Q2: [SOURCE_1] giao trinh Luat lao dong CB 2005 (1) | tr.3 | BÀI 1 > KHÁI NIỆM LUẬT LAO ĐỘNG VIỆT NAM > I - ĐỐI TƯỢNG VÀ | 0.9984 [SOURCE_2] giao trinh Luat lao dong CB 2005 (1) | tr.7 | 2 - Phương pháp điều chỉnh của luật lao động | 0.9587 [SOURCE_3] giao trinh Luat lao dong CB 2005 (1) | tr.7 | (7) - Quan hệ về quản lý lao động | 0.9279 [SOURCE_4] giao trinh Luat lao dong CB 2005 (1) | tr.3 | a - Quan hệ lao động | 0.8305 [SOURCE_5] giao trinh Luat lao dong CB 2005 (1) | tr.6 | (4) Quan hệ về bảo hiểm xã hội | 0.8054 | R2: gemini-3.5-flash-lite | S2: 56.3 | T2: 1 | U2: 0.875 | V2: Yes | W2: Yes | X2: PASS | Z2: PASS | AA2: =IF(Z2="",X2,Z2) | AC2: [AI] Đồng ý với chấm tự động
A3: LAW_A_002 | B3: Definition | C3: Quan hệ lao động được giáo trình mô tả là gì? | D3: Là quan hệ giữa con người với con người trong lao động nhằm tạo ra các giá trị vật chất, tinh thần phục vụ bản thân và xã hội. | E3: Căn cứ: phần “Bài 1 - Quan hệ lao động”, trang 3. Nội dung được tài liệu xác nhận: Là quan hệ giữa con người với con người trong lao động nhằm tạo ra các giá trị vật chất, tinh thần phục vụ bản thân và xã hội. | F3: 3 | G3: Bài 1 - Quan hệ lao động | H3: lao động | giá trị vật chất | tinh thần | I3: Easy | J3: Single Chunk | K3: Yes | L3: Answer from document | N3: giao trinh Luat lao dong CB 2005 (1) | O3: Dựa trên tài liệu được cung cấp, quan hệ lao động được mô tả như sau: * Quan hệ giữa con người với con người trong lao động nhằm tạo ra những giá trị vật chất, tinh thần phục vụ chính bản thân và xã hội được gọi là quan hệ lao động [SOURCE_3]. * Quan hệ lao động là biểu hiện một mặt của quan hệ sản xuất và chịu sự chi phối của quan hệ sở hữu [SOURCE_3]. * Ở đâu có tổ chức lao động, có hợp tác và phân công lao động thì ở đó tồn tại quan hệ lao động [SOURCE_3]. Trong nền kinh tế thị trường với sự tham gia của nhiều thành phần kinh tế, các quan hệ lao động ngày càng trở nên đa dạng, phức tạp và đan xen lẫn nhau [SOURCE_3]. * Quan hệ lao động vừa có tính kinh tế, vừa có tính xã hội [SOURCE_1]. * Theo quy định, quan hệ lao động là quan hệ xã hội phát sinh trong việc thuê mướn, sử dụng lao động, trả lương giữa người lao động và người sử dụng lao động [SOURCE_4]. Quan hệ này giữa người lao động hoặc tập thể lao động với người sử dụng lao động được xác lập qua đối thoại, thương lượng, thỏa thuận theo nguyên tắc tự nguyện, thiện chí, bình đẳng, hợp tác, tôn trọng quyền và lợi ích hợp pháp của nhau [SOURCE_5]. | P3: [SOURCE_1] giao trinh Luat lao dong CB 2005 (1) | tr.13 | Giáo trình Luật Lao động cơ bản | 0.9737 [SOURCE_3] giao trinh Luat lao dong CB 2005 (1) | tr.3 | a - Quan hệ lao động | 0.8496 [SOURCE_4] luu-ban-nhap-tu-dong-3-4 | tr.69 | Điều 3. Giải thích từ ngữ ữ | 0.8055 [SOURCE_5] luu-ban-nhap-tu-dong-3-4 | tr.72 | Điều 7. Quan hệ lao động | 0.7175 | Q3: [SOURCE_1] giao trinh Luat lao dong CB 2005 (1) | tr.13 | Giáo trình Luật Lao động cơ bản | 0.9737 [SOURCE_2] giao trinh Luat lao dong CB 2005 (1) | tr.3 | a - Quan hệ lao động | 0.8655 [SOURCE_3] giao trinh Luat lao dong CB 2005 (1) | tr.3 | a - Quan hệ lao động | 0.8496 [SOURCE_4] luu-ban-nhap-tu-dong-3-4 | tr.69 | Điều 3. Giải thích từ ngữ ữ | 0.8055 [SOURCE_5] luu-ban-nhap-tu-dong-3-4 | tr.72 | Điều 7. Quan hệ lao động | 0.7175 | R3: gemini-3.5-flash-lite | S3: 23.3 | T3: 1 | U3: 1 | V3: Yes | W3: Yes | X3: PASS | Z3: PASS | AA3: =IF(Z3="",X3,Z3) | AC3: [AI] Đồng ý với chấm tự động
A4: LAW_A_003 | B4: List | C4: Giáo trình liệt kê những quan hệ nào liên quan đến quan hệ lao động? | D4: Gồm quan hệ về việc làm, học nghề, bồi thường thiệt hại, bảo hiểm xã hội, quan hệ với Công đoàn/đại diện tập thể lao động, giải quyết tranh chấp và đình công, và quản lý lao động. | E4: Căn cứ: phần “Bài 1 - Các quan hệ liên quan”, trang 5. Nội dung được tài liệu xác nhận: Gồm quan hệ về việc làm, học nghề, bồi thường thiệt hại, bảo hiểm xã hội, quan hệ với Công đoàn/đại diện tập thể lao động, giải quyết tranh chấp và đình công, và quản lý lao động. | F4: 5 | G4: Bài 1 - Các quan hệ liên quan | H4: việc làm | học nghề | bồi thường | BHXH | công đoàn | tranh chấp | quản lý | I4: Easy | J4: Single Chunk | K4: Yes | L4: Answer from document | N4: giao trinh Luat lao dong CB 2005 (1) | O4: Dựa trên tài liệu được cung cấp, ngoài quan hệ lao động làm công ăn lương là quan hệ chủ yếu, Luật lao động còn điều chỉnh các quan hệ xã hội khác liên quan chặt chẽ với quan hệ lao động bao gồm [SOURCE_1]: * Quan hệ về việc làm [SOURCE_1] * Quan hệ học nghề [SOURCE_1] * Quan hệ về bồi thường thiệt hại [SOURCE_1] * Quan hệ về bảo hiểm xã hội [SOURCE_1] * Quan hệ giữa người sử dụng lao động với tổ chức Công đoàn, đại diện của tập thể người lao động [SOURCE_1] * Quan hệ về giải quyết các tranh chấp lao động và các cuộc đình công [SOURCE_1] * Quan hệ về quản lý lao động [SOURCE_1] | P4: [SOURCE_1] giao trinh Luat lao dong CB 2005 (1) | tr.4 | b - Các quan hệ liên quan đến quan hệ lao động | 0.9891 | Q4: [SOURCE_1] giao trinh Luat lao dong CB 2005 (1) | tr.4 | b - Các quan hệ liên quan đến quan hệ lao động | 0.9891 [SOURCE_2] giao trinh Luat lao dong CB 2005 (1) | tr.13 | Giáo trình Luật Lao động cơ bản | 0.9326 [SOURCE_3] giao trinh Luat lao dong CB 2005 (1) | tr.3 | a - Quan hệ lao động | 0.9083 [SOURCE_4] luu-ban-nhap-tu-dong-3-4 | tr.72 | Điều 7. Quan hệ lao động | 0.8941 [SOURCE_5] giao trinh Luat lao dong CB 2005 (1) | tr.3 | a - Quan hệ lao động | 0.891 | R4: gemini-3.5-flash-lite | S4: 20.6 | T4: 1 | U4: 1 | V4: Yes | W4: Yes | X4: PASS | Z4: PASS | AA4: =IF(Z4="",X4,Z4) | AC4: [AI] Đồng ý với chấm tự động
A5: LAW_A_004 | B5: Definition | C5: Theo giáo trình, quan hệ pháp luật lao động là gì? | D5: Là các quan hệ phát sinh trong quá trình sử dụng sức lao động, được các quy phạm pháp luật lao động điều chỉnh. | E5: Căn cứ: phần “Bài 2 - Khái niệm”, trang 14. Nội dung được tài liệu xác nhận: Là các quan hệ phát sinh trong quá trình sử dụng sức lao động, được các quy phạm pháp luật lao động điều chỉnh. | F5: 14 | G5: Bài 2 - Khái niệm | H5: sử dụng sức lao động | quy phạm pháp luật lao động | I5: Easy | J5: Single Chunk | K5: Yes | L5: Answer from document | N5: giao trinh Luat lao dong CB 2005 (1) | O5: Dựa trên giáo trình, quan hệ pháp luật lao động là các quan hệ phát sinh trong quá trình sử dụng sức lao động của người lao động ở các cơ quan Nhà nước, các tổ chức, các hợp tác xã, các doanh nghiệp thuộc mọi thành phần kinh tế và các gia đình hay cá nhân có thuê mướn lao động, được các quy phạm pháp luật lao động điều chỉnh [SOURCE_2]. | P5: [SOURCE_2] giao trinh Luat lao dong CB 2005 (1) | tr.14 | BÀI 2 > QUAN HỆ PHÁP LUẬT LAO ĐỘNG > I - KHÁI NIỆM VÀ ĐẶC ĐI | 0.9835 | Q5: [SOURCE_1] giao trinh Luat lao dong CB 2005 (1) | tr.13 | Giáo trình Luật Lao động cơ bản | 0.9936 [SOURCE_2] giao trinh Luat lao dong CB 2005 (1) | tr.14 | BÀI 2 > QUAN HỆ PHÁP LUẬT LAO ĐỘNG > I - KHÁI NIỆM VÀ ĐẶC ĐI | 0.9835 [SOURCE_3] giao trinh Luat lao dong CB 2005 (1) | tr.14 | 2. Đặc điểm của quan hệ pháp luật lao động | 0.9708 [SOURCE_4] giao trinh Luat lao dong CB 2005 (1) | tr.14 | 2. Đặc điểm của quan hệ pháp luật lao động | 0.9608 [SOURCE_5] giao trinh Luat lao dong CB 2005 (1) | tr.18 | 2. Nội dung của quan hệ pháp luật lao động | 0.9575 | R5: gemini-3.5-flash-lite | S5: 14.2 | T5: 1 | U5: 1 | V5: Yes | W5: Yes | X5: PASS | Z5: PASS | AA5: =IF(Z5="",X5,Z5) | AC5: [AI] Đồng ý với chấm tự động
A6: LAW_A_005 | B6: Direct Fact | C6: Ba loại quan hệ về việc làm chủ yếu được giáo trình nêu là gì? | D6: Quan hệ bảo đảm việc làm giữa Nhà nước và NLĐ; giữa NSDLĐ và NLĐ; và giữa NLĐ với các trung tâm dịch vụ việc làm. | E6: Căn cứ: phần “Bài 1 - Quan hệ việc làm”, trang 5. Nội dung được tài liệu xác nhận: Quan hệ bảo đảm việc làm giữa Nhà nước và NLĐ; giữa NSDLĐ và NLĐ; và giữa NLĐ với các trung tâm dịch vụ việc làm. | F6: 5 | G6: Bài 1 - Quan hệ việc làm | H6: Nhà nước | NSDLĐ | trung tâm dịch vụ việc làm | I6: Easy | J6: Single Chunk | K6: Yes | L6: Answer from document | N6: giao trinh Luat lao dong CB 2005 (1) | O6: Ba loại quan hệ về việc làm chủ yếu được nêu trong giáo trình bao gồm: 1. Quan hệ về đảm bảo việc làm giữa Nhà nước và người lao động [SOURCE_1]. 2. Quan hệ về đảm bảo việc làm giữa người sử dụng lao động và người lao động [SOURCE_1]. 3. Quan hệ giữa người lao động và các trung tâm dịch vụ việc làm [SOURCE_1]. | P6: [SOURCE_1] giao trinh Luat lao dong CB 2005 (1) | tr.5 | (1) Quan hệ về việc làm | 0.9905 | Q6: [SOURCE_1] giao trinh Luat lao dong CB 2005 (1) | tr.5 | (1) Quan hệ về việc làm | 0.9905 [SOURCE_2] giao trinh Luat lao dong CB 2005 (1) | tr.4 | b - Các quan hệ liên quan đến quan hệ lao động | 0.5222 | R6: gemini-3.5-flash-lite | S6: 18.6 | T6: 1 | U6: 1 | V6: Yes | W6: Yes | X6: PASS | Z6: PASS | AA6: =IF(Z6="",X6,Z6) | AC6: [AI] Đồng ý với chấm tự động
A7: LAW_A_006 | B7: Concept | C7: Quan hệ học nghề có thể tồn tại dưới những dạng nào? | D7: Có thể là quan hệ độc lập hoặc là quan hệ phụ thuộc quan hệ lao động. | E7: Căn cứ: phần “Bài 1 - Quan hệ học nghề”, trang 5. Nội dung được tài liệu xác nhận: Có thể là quan hệ độc lập hoặc là quan hệ phụ thuộc quan hệ lao động. | F7: 5 | G7: Bài 1 - Quan hệ học nghề | H7: độc lập | phụ thuộc quan hệ lao động | I7: Easy | J7: Single Chunk | K7: Yes | L7: Answer from document | N7: giao trinh Luat lao dong CB 2005 (1) | O7: Dựa trên tài liệu được cung cấp, quan hệ học nghề có thể tồn tại dưới hai dạng: vừa có thể là một quan hệ độc lập, vừa có thể là một quan hệ phụ thuộc quan hệ lao động [SOURCE_1]. | P7: [SOURCE_1] giao trinh Luat lao dong CB 2005 (1) | tr.5 | (2) Quan hệ học nghề | 0.8816 | Q7: [SOURCE_1] giao trinh Luat lao dong CB 2005 (1) | tr.5 | (2) Quan hệ học nghề | 0.8816 [SOURCE_2] giao trinh Luat lao dong CB 2005 (1) | tr.5 | (2) Quan hệ học nghề | 0.4338 | R7: gemini-3.5-flash-lite | S7: 18.6 | T7: 1 | U7: 1 | V7: Yes | W7: Yes | X7: PASS | Z7: PASS | AA7: =IF(Z7="",X7,Z7) | AC7: [AI] Đồng ý với chấm tự động
A8: LAW_A_007 | B8: Definition | C8: Theo giáo trình, tiền lương được nhìn nhận như thế nào trong quan hệ lao động? | D8: Tiền lương được xem là giá cả của sức lao động và việc trả lương dựa trên thỏa thuận, trong khuôn khổ pháp luật. | E8: Căn cứ: phần “Bài 1/Bài 6 - Tiền lương”, trang None. Nội dung được tài liệu xác nhận: Tiền lương được xem là giá cả của sức lao động và việc trả lương dựa trên thỏa thuận, trong khuôn khổ pháp luật. | G8: Bài 1/Bài 6 - Tiền lương | H8: giá cả sức lao động | thỏa thuận | I8: Easy | J8: Single Chunk | K8: Yes | L8: Answer from document | N8: giao trinh Luat lao dong CB 2005 (1) | O8: Dựa trên tài liệu được cung cấp, tiền lương được nhìn nhận ở các khía cạnh sau: * Bên cạnh mục tiêu kinh tế như lợi nhuận, tiền lương là một trong những vấn đề kinh tế gắn liền với mục tiêu xã hội mà Luật Lao động phải giải quyết trong quá trình lao động và ngay tại các doanh nghiệp [SOURCE_1]. * Tiền lương là số lượng tiền tệ mà người sử dụng lao động trả cho người lao động khi người lao động hoàn thành công việc theo chức năng, nhiệm vụ do pháp luật quy định, hoặc do hai bên đã thoả thuận trong hợp đồng lao động [SOURCE_2]. * Tiền lương do hai bên thoả thuận trong hợp đồng lao động và được trả theo năng suất lao động, chất lượng và hiệu quả công việc [SOURCE_2]. Mức lương này không được thấp hơn mức lương tối thiểu do Nhà nước quy định [SOURCE_2]. * Lương được trả bằng tiền mặt, hoặc có thể trả một phần bằng séc/ngân phiếu do Nhà nước phát hành nếu hai bên thỏa thuận với điều kiện không gây thiệt hại, phiền hà cho người lao động [SOURCE_2]. * Theo quy định tại Điều 90, tiền lương là số tiền mà người sử dụng lao động trả cho người lao động theo thỏa thuận để thực hiện công việc, bao gồm mức lương theo công việc hoặc chức danh, phụ cấp lương và các khoản bổ sung khác [SOURCE_3]. Trong đó, mức lương theo công việc hoặc chức danh không được thấp hơn mức lương tối thiểu, và người sử dụng lao động phải bảo đảm trả lương bình đẳng, không phân biệt giới tính đối với người lao động làm công việc có giá trị như nhau [SOURCE_3]. | P8: [SOURCE_1] giao trinh Luat lao dong CB 2005 (1) | tr.13 | Giáo trình Luật Lao động cơ bản | 0.7146 [SOURCE_2] giao trinh Luat lao dong CB 2005 (1) | tr.58 | BÀI 6 > TIỀN LƯƠNG > I. KHÁI QUÁT CHUNG VỀ TIỀN LƯƠNG > 1. Đ | 0.4023 [SOURCE_3] luu-ban-nhap-tu-dong-3-4 | tr.31 | Chương VI > Điều 90. Tiền lương | 0.3612 | Q8: [SOURCE_1] giao trinh Luat lao dong CB 2005 (1) | tr.13 | Giáo trình Luật Lao động cơ bản | 0.7146 [SOURCE_2] giao trinh Luat lao dong CB 2005 (1) | tr.58 | BÀI 6 > TIỀN LƯƠNG > I. KHÁI QUÁT CHUNG VỀ TIỀN LƯƠNG > 1. Đ | 0.4023 [SOURCE_3] luu-ban-nhap-tu-dong-3-4 | tr.31 | Chương VI > Điều 90. Tiền lương | 0.3612 | R8: gemini-3.5-flash-lite | S8: 18.8 | T8: 0.5 | U8: 0.73684211 | V8: Yes | W8: n/a | X8: PARTIAL | Y8: Thiếu từ khóa (50%) | Z8: PARTIAL | AA8: =IF(Z8="",X8,Z8) | AC8: [AI] Thiếu ý 'tiền lương là giá cả sức lao động'; có ý thỏa thuận và mức tối thiểu
A9: LAW_A_008 | B9: Direct Fact | C9: Theo giáo trình, làm thêm vào ngày thường được trả ít nhất bao nhiêu phần trăm? | D9: Ít nhất bằng 150% đơn giá tiền lương hoặc tiền lương thực trả của công việc đang làm. | E9: Căn cứ: phần “Bài 6 - Trả lương làm thêm giờ”, trang 59. Nội dung được tài liệu xác nhận: Ít nhất bằng 150% đơn giá tiền lương hoặc tiền lương thực trả của công việc đang làm. | F9: 59 | G9: Bài 6 - Trả lương làm thêm giờ | H9: 150% | ngày thường | I9: Medium | J9: Single Chunk | K9: Yes | L9: Answer from document | N9: giao trinh Luat lao dong CB 2005 (1) | O9: Theo tài liệu, người lao động làm thêm giờ vào ngày thường được trả lương ít nhất bằng 150% [SOURCE_1], [SOURCE_2], [SOURCE_3], [SOURCE_4], [SOURCE_5]. | P9: [SOURCE_1] so-tay-kien-thuc-phap-luat-lao-dong-cdi | tr.19 | Trả lời: | 0.9585 [SOURCE_2] giao trinh Luat lao dong CB 2005 (1) | tr.59 | 4. Trả lương khi làm thêm giờ | 0.9547 [SOURCE_3] Văn-bản-hợp-nhất-18-VBHN-VPQH | tr.38 | Điều 98. Tiền lương làm thêm giờ, làm việc vào ban đêm | 0.9278 [SOURCE_4] ILO-VCCI_Labour-Law-Guide-Book-V04-Final | tr.100 | 1. Tiền lương làm thêm giờ225 > (a) Đối với NLĐ hưởng lương | 0.9243 [SOURCE_5] giao trinh Luat lao dong CB 2005 (1) | tr.80 | · Các điều kiện và nguyên tắc làm thêm đến 300 giờ trong một | 0.8973 | Q9: [SOURCE_1] so-tay-kien-thuc-phap-luat-lao-dong-cdi | tr.19 | Trả lời: | 0.9585 [SOURCE_2] giao trinh Luat lao dong CB 2005 (1) | tr.59 | 4. Trả lương khi làm thêm giờ | 0.9547 [SOURCE_3] Văn-bản-hợp-nhất-18-VBHN-VPQH | tr.38 | Điều 98. Tiền lương làm thêm giờ, làm việc vào ban đêm | 0.9278 [SOURCE_4] ILO-VCCI_Labour-Law-Guide-Book-V04-Final | tr.100 | 1. Tiền lương làm thêm giờ225 > (a) Đối với NLĐ hưởng lương | 0.9243 [SOURCE_5] giao trinh Luat lao dong CB 2005 (1) | tr.80 | · Các điều kiện và nguyên tắc làm thêm đến 300 giờ trong một | 0.8973 | R9: gemini-3.5-flash-lite | S9: 15.8 | T9: 1 | U9: 0.53333333 | V9: Yes | W9: Yes | X9: PASS | Z9: PASS | AA9: =IF(Z9="",X9,Z9) | AC9: [AI] Đồng ý với chấm tự động
A10: LAW_A_009 | B10: Direct Fact | C10: Theo giáo trình, làm thêm vào ngày nghỉ hằng tuần được trả ít nhất bao nhiêu? | D10: Ít nhất bằng 200%. | E10: Căn cứ: phần “Bài 6 - Trả lương làm thêm giờ”, trang 59. Nội dung được tài liệu xác nhận: Ít nhất bằng 200%. | F10: 59 | G10: Bài 6 - Trả lương làm thêm giờ | H10: 200% | ngày nghỉ hàng tuần | I10: Medium | J10: Single Chunk | K10: Yes | L10: Answer from document | N10: giao trinh Luat lao dong CB 2005 (1) | O10: Theo tài liệu, người lao động làm thêm giờ vào ngày nghỉ hằng tuần được trả lương tính theo đơn giá tiền lương hoặc tiền lương thực trả (hoặc công việc đang làm) với mức ít nhất bằng 200% [SOURCE_1], [SOURCE_2], [SOURCE_3], [SOURCE_4], [SOURCE_5]. | P10: [SOURCE_1] so-tay-kien-thuc-phap-luat-lao-dong-cdi | tr.19 | Trả lời: | 0.9454 [SOURCE_2] Văn-bản-hợp-nhất-18-VBHN-VPQH | tr.38 | Điều 98. Tiền lương làm thêm giờ, làm việc vào ban đêm | 0.9207 [SOURCE_3] ILO-VCCI_Labour-Law-Guide-Book-V04-Final | tr.100 | 1. Tiền lương làm thêm giờ225 > (a) Đối với NLĐ hưởng lương | 0.9207 [SOURCE_4] giao trinh Luat lao dong CB 2005 (1) | tr.59 | 4. Trả lương khi làm thêm giờ | 0.9096 [SOURCE_5] giao trinh Luat lao dong CB 2005 (1) | tr.80 | · Các điều kiện và nguyên tắc làm thêm đến 300 giờ trong một | 0.8598 | Q10: [SOURCE_1] so-tay-kien-thuc-phap-luat-lao-dong-cdi | tr.19 | Trả lời: | 0.9454 [SOURCE_2] Văn-bản-hợp-nhất-18-VBHN-VPQH | tr.38 | Điều 98. Tiền lương làm thêm giờ, làm việc vào ban đêm | 0.9207 [SOURCE_3] ILO-VCCI_Labour-Law-Guide-Book-V04-Final | tr.100 | 1. Tiền lương làm thêm giờ225 > (a) Đối với NLĐ hưởng lương | 0.9207 [SOURCE_4] giao trinh Luat lao dong CB 2005 (1) | tr.59 | 4. Trả lương khi làm thêm giờ | 0.9096 [SOURCE_5] giao trinh Luat lao dong CB 2005 (1) | tr.80 | · Các điều kiện và nguyên tắc làm thêm đến 300 giờ trong một | 0.8598 | R10: gemini-3.5-flash-lite | S10: 18 | T10: 0.5 | U10: 1 | V10: Yes | W10: Yes | X10: PARTIAL | Y10: Thiếu từ khóa (50%) | Z10: PASS | AA10: =IF(Z10="",X10,Z10) | AC10: [AI] Đúng 200%, trích giáo trình tr.59; scorer chấm thiếu từ khóa oan
A11: LAW_A_010 | B11: Direct Fact | C11: Theo giáo trình, làm thêm vào ngày lễ/ngày nghỉ hưởng lương được trả ít nhất bao nhiêu? | D11: Ít nhất bằng 300% theo quy định được tài liệu trình bày. | E11: Căn cứ: phần “Bài 6 - Trả lương làm thêm giờ”, trang 59. Nội dung được tài liệu xác nhận: Ít nhất bằng 300% theo quy định được tài liệu trình bày. | F11: 59 | G11: Bài 6 - Trả lương làm thêm giờ | H11: 300% | ngày lễ | nghỉ hưởng lương | I11: Medium | J11: Single Chunk | K11: Yes | L11: Answer from document | N11: giao trinh Luat lao dong CB 2005 (1) | O11: Theo tài liệu, người lao động làm thêm giờ vào ngày lễ, ngày nghỉ có hưởng lương được trả lương ít nhất bằng 300% (chưa kể tiền lương của ngày lễ, ngày nghỉ có hưởng lương đối với người lao động hưởng lương ngày) [SOURCE_1], [SOURCE_2], [SOURCE_3], [SOURCE_5]. | P11: [SOURCE_1] so-tay-kien-thuc-phap-luat-lao-dong-cdi | tr.19 | Trả lời: | 0.9537 [SOURCE_2] giao trinh Luat lao dong CB 2005 (1) | tr.59 | 4. Trả lương khi làm thêm giờ | 0.9412 [SOURCE_3] Văn-bản-hợp-nhất-18-VBHN-VPQH | tr.38 | Điều 98. Tiền lương làm thêm giờ, làm việc vào ban đêm | 0.9356 [SOURCE_5] ILO-VCCI_Labour-Law-Guide-Book-V04-Final | tr.100 | 1. Tiền lương làm thêm giờ225 > (a) Đối với NLĐ hưởng lương | 0.9082 | Q11: [SOURCE_1] so-tay-kien-thuc-phap-luat-lao-dong-cdi | tr.19 | Trả lời: | 0.9537 [SOURCE_2] giao trinh Luat lao dong CB 2005 (1) | tr.59 | 4. Trả lương khi làm thêm giờ | 0.9412 [SOURCE_3] Văn-bản-hợp-nhất-18-VBHN-VPQH | tr.38 | Điều 98. Tiền lương làm thêm giờ, làm việc vào ban đêm | 0.9356 [SOURCE_4] luu-ban-nhap-tu-dong-3-4 | tr.424 | Điều 25. Tiền lương làm thêm giờ, làm việc vào ban đêm | 0.9305 [SOURCE_5] ILO-VCCI_Labour-Law-Guide-Book-V04-Final | tr.100 | 1. Tiền lương làm thêm giờ225 > (a) Đối với NLĐ hưởng lương | 0.9082 | R11: gemini-3.5-flash-lite | S11: 16.2 | T11: 1 | U11: 0.5 | V11: Yes | W11: Yes | X11: PASS | Z11: PASS | AA11: =IF(Z11="",X11,Z11) | AC11: [AI] Đồng ý với chấm tự động
A12: LAW_A_011 | B12: Rule | C12: Giới hạn làm thêm giờ mà giáo trình nêu là bao nhiêu? | D12: Không quá 4 giờ trong một ngày, 200 giờ trong một năm; một số trường hợp đặc biệt không quá 300 giờ trong một năm. | E12: Căn cứ: phần “Bài 7 - Làm thêm giờ”, trang 79. Nội dung được tài liệu xác nhận: Không quá 4 giờ trong một ngày, 200 giờ trong một năm; một số trường hợp đặc biệt không quá 300 giờ trong một năm. | F12: 79 | G12: Bài 7 - Làm thêm giờ | H12: 4 giờ/ngày | 200 giờ/năm | 300 giờ/năm | I12: Medium | J12: Single Chunk | K12: Yes | L12: Answer from document | N12: giao trinh Luat lao dong CB 2005 (1) | O12: Dựa trên tài liệu được cung cấp, giới hạn làm thêm giờ được quy định như sau: * **Trong ngày và trong tuần:** Tổng số giờ làm thêm không quá 50% số giờ làm việc bình thường trong 01 ngày khi làm thêm vào ngày làm việc bình thường [SOURCE_3, SOURCE_4]. Trường hợp áp dụng quy định thời giờ làm việc bình thường theo tuần, tổng số giờ làm việc bình thường và số giờ làm thêm không quá 12 giờ trong 01 ngày [SOURCE_3, SOURCE_4]. Quy định này cũng áp dụng tương tự đối với trường hợp làm việc không trọn thời gian khi làm thêm vào ngày nghỉ lễ, tết và ngày nghỉ hằng tuần [SOURCE_4]. * **Trong tháng:** Tổng số giờ làm thêm của người lao động không quá 40 giờ trong 01 tháng (tăng từ 30 giờ lên 40 giờ so với quy định tại Bộ luật Lao động 2012) [SOURCE_4]. (Lưu ý tại Điều 106 đề cập mức không quá 30 giờ trong 01 tháng [SOURCE_3], nhưng phần phân tích chi tiết của tài liệu nêu rõ giới hạn tối đa là 40 giờ trong 01 tháng từ ngày 01/01/2021 [SOURCE_4]). * **Trong năm:** Tổng số giờ làm thêm không quá 200 giờ trong 01 năm, trừ một số trường hợp đặc biệt được Chính phủ quy định thì được làm thêm giờ không quá 300 giờ trong 01 năm [SOURCE_3]. | P12: [SOURCE_3] luu-ban-nhap-tu-dong-3-4 | tr.101 | Điều 106. Làm thêm giờ | 0.4728 [SOURCE_4] ILO-VCCI_Labour-Law-Guide-Book-V04-Final | tr.111 | (i) Giới hạn số giờ làm thêm trong ngày và trong tháng | 0.436 | Q12: [SOURCE_1] ILO-VCCI_Labour-Law-Guide-Book-V04-Final | tr.112 | (ii) Giới hạn số giờ làm thêm trong năm | 0.6783 [SOURCE_2] ILO-VCCI_Labour-Law-Guide-Book-V04-Final | tr.112 | (ii) Giới hạn số giờ làm thêm trong năm | 0.4942 [SOURCE_3] luu-ban-nhap-tu-dong-3-4 | tr.101 | Điều 106. Làm thêm giờ | 0.4728 [SOURCE_4] ILO-VCCI_Labour-Law-Guide-Book-V04-Final | tr.111 | (i) Giới hạn số giờ làm thêm trong ngày và trong tháng | 0.436 | R12: gemini-3.5-flash-lite | S12: 18.8 | T12: 0.66666667 | U12: 1 | V12: No | W12: No | X12: PARTIAL | Y12: Thiếu từ khóa (67%); Không trích tài liệu mong đợi (không có trong ngữ cảnh); Không trích đúng trang 79 (±1) | Z12: FAIL | AA12: =IF(Z12="",X12,Z12) | AB12: DEF-05 | AC12: [AI] Sai pháp lý: trả lời 50%/40 giờ/tháng theo BLLĐ 2019 (ILO, bộ tổng hợp) thay vì 4 giờ/ngày, 200 giờ/năm của giáo trình
A13: LAW_A_012 | B13: Concept | C13: Vì sao phương pháp thỏa thuận có vai trò quan trọng trong Luật lao động theo giáo trình? | D13: Vì quan hệ lao động có bản chất tự do thương lượng; các bên thỏa thuận trên cơ sở tự nguyện, bình đẳng để cùng có lợi và thực hiện nghĩa vụ. | E13: Căn cứ: phần “Bài 1 - Phương pháp điều chỉnh” Nội dung được tài liệu xác nhận: Vì quan hệ lao động có bản chất tự do thương lượng; các bên thỏa thuận trên cơ sở tự nguyện, bình đẳng để cùng có lợi và thực hiện nghĩa vụ. | G13: Bài 1 - Phương pháp điều chỉnh | H13: thỏa thuận | tự nguyện | bình đẳng | cùng có lợi | I13: Medium | J13: Single Chunk | K13: Yes | L13: Answer from document | N13: giao trinh Luat lao dong CB 2005 (1) | O13: Dựa trên tài liệu được cung cấp, phương pháp thỏa thuận có vai trò quan trọng vì những lý do sau: * Phương pháp này chủ yếu được áp dụng trong trường hợp xác lập quan hệ lao động giữa người lao động và người sử dụng lao động, cũng như trong việc xác lập thỏa ước lao động tập thể [SOURCE_2]. * Xuất phát từ bản chất của quan hệ lao động là tự do thương lượng, các bên cùng nhau thỏa thuận các vấn đề liên quan trong quá trình lao động trên cơ sở tự nguyện và bình đẳng [SOURCE_1], [SOURCE_2]. * Việc thỏa thuận nhằm đảm bảo cho hai bên cùng có lợi và tạo điều kiện để các bên thực hiện tốt các nghĩa vụ của mình [SOURCE_1], [SOURCE_2]. | P13: [SOURCE_1] giao trinh Luat lao dong CB 2005 (1) | tr.7 | a - Phương pháp thỏa thuận | 0.9808 [SOURCE_2] giao trinh Luat lao dong CB 2005 (1) | tr.7 | a - Phương pháp thỏa thuận | 0.9449 | Q13: [SOURCE_1] giao trinh Luat lao dong CB 2005 (1) | tr.7 | a - Phương pháp thỏa thuận | 0.9808 [SOURCE_2] giao trinh Luat lao dong CB 2005 (1) | tr.7 | a - Phương pháp thỏa thuận | 0.9449 [SOURCE_3] giao trinh Luat lao dong CB 2005 (1) | tr.49 | 4. Ý nghĩa của thỏa ước lao động tập thể | 0.3944 | R13: gemini-3.5-flash-lite | S13: 18.9 | T13: 1 | U13: 1 | V13: Yes | W13: n/a | X13: PASS | Z13: PASS | AA13: =IF(Z13="",X13,Z13) | AC13: [AI] Đồng ý với chấm tự động
A14: LAW_A_013 | B14: Comparison | C14: Phương pháp thỏa thuận trong Luật lao động khác Luật dân sự ở điểm nào theo giáo trình? | D14: Giáo trình cho rằng trong dân sự các chủ thể bình đẳng và độc lập về địa vị kinh tế nên thỏa thuận được sử dụng triệt để; trong lao động, thỏa thuận chịu ảnh hưởng bởi quan hệ phụ thuộc và các giới hạn bảo vệ lao động. | E14: Căn cứ: phần “Bài 1 - Phương pháp điều chỉnh” Nội dung được tài liệu xác nhận: Giáo trình cho rằng trong dân sự các chủ thể bình đẳng và độc lập về địa vị kinh tế nên thỏa thuận được sử dụng triệt để; trong lao động, thỏa thuận chịu ảnh hưởng bởi quan hệ phụ thuộc và các giới hạn bảo vệ lao động. | G14: Bài 1 - Phương pháp điều chỉnh | H14: dân sự | lao động | bình đẳng | phụ thuộc | I14: Medium | J14: Multiple Chunks | K14: Yes | L14: Answer from document | N14: giao trinh Luat lao dong CB 2005 (1) | O14: Theo tài liệu, phương pháp thỏa thuận trong Luật lao động khác với phương pháp thỏa thuận trong Luật dân sự ở những điểm sau: * **Về địa vị và tính độc lập của các chủ thể:** Trong Luật dân sự, các chủ thể tham gia quan hệ xã hội bình đẳng và độc lập với nhau về địa vị kinh tế [SOURCE_1]. Ngược lại, trong Luật lao động, các chủ thể tham gia quan hệ lao động không bình đẳng về địa vị và không độc lập với nhau về tổ chức [SOURCE_1]. * **Về mức độ sử dụng và phạm vi tác động:** Trong Luật dân sự, phương pháp thỏa thuận được sử dụng triệt để và tác động lên các quan hệ dân sự trong suốt quá trình từ khi xác lập đến khi chấm dứt [SOURCE_1]. Trong Luật lao động, tuy các chủ thể thực hiện quyền tự định đoạt, tự do, thương lượng, tự nguyện thỏa thuận trong khuôn khổ pháp luật nhằm đảm bảo cùng có lợi, nhưng quan hệ lao động luôn có yếu tố quản lý [SOURCE_1]. * **Sự can thiệp của Nhà nước:** Để điều hòa mối quan hệ không bình đẳng giữa các bên trong Luật lao động, Nhà nước bằng pháp luật đã đặt ra các quy định nhằm bảo vệ người lao động, nâng cao vị trí của người lao động để họ bình đẳng với người sử dụng lao động [SOURCE_1]. | P14: [SOURCE_1] giao trinh Luat lao dong CB 2005 (1) | tr.7 | a - Phương pháp thỏa thuận | 0.9941 | Q14: [SOURCE_1] giao trinh Luat lao dong CB 2005 (1) | tr.7 | a - Phương pháp thỏa thuận | 0.9941 [SOURCE_2] giao trinh Luat lao dong CB 2005 (1) | tr.7 | a - Phương pháp thỏa thuận | 0.8212 | R14: gemini-3.5-flash-lite | S14: 19.7 | T14: 0.75 | U14: 0.73684211 | V14: Yes | W14: n/a | X14: PASS | Z14: PASS | AA14: =IF(Z14="",X14,Z14) | AC14: [AI] Đồng ý với chấm tự động
A15: LAW_A_014 | B15: Concept | C15: Quan hệ bồi thường thiệt hại trong lao động phát sinh khi nào? | D15: Phát sinh khi một chủ thể trong quá trình thực hiện quyền, nghĩa vụ lao động gây thiệt hại về sức khỏe, tính mạng, tài sản hoặc lợi ích của bên kia. | E15: Căn cứ: phần “Bài 1 - Bồi thường thiệt hại”, trang 6. Nội dung được tài liệu xác nhận: Phát sinh khi một chủ thể trong quá trình thực hiện quyền, nghĩa vụ lao động gây thiệt hại về sức khỏe, tính mạng, tài sản hoặc lợi ích của bên kia. | F15: 6 | G15: Bài 1 - Bồi thường thiệt hại | H15: thiệt hại | sức khỏe | tính mạng | tài sản | I15: Medium | J15: Single Chunk | K15: Yes | L15: Answer from document | N15: giao trinh Luat lao dong CB 2005 (1) | O15: Dựa trên tài liệu được cung cấp, quan hệ về bồi thường thiệt hại phát sinh khi các chủ thể tham gia quan hệ lao động thực hiện các quyền và nghĩa vụ lao động của mình, nhưng một trong các chủ thể đã gây thiệt hại về sức khỏe, tính mạng, tài sản hoặc lợi ích của bên kia [SOURCE_1]. | P15: [SOURCE_1] giao trinh Luat lao dong CB 2005 (1) | tr.5 | (2) Quan hệ học nghề | 0.9279 | Q15: [SOURCE_1] giao trinh Luat lao dong CB 2005 (1) | tr.5 | (2) Quan hệ học nghề | 0.9279 [SOURCE_2] giao trinh Luat lao dong CB 2005 (1) | tr.5 | (2) Quan hệ học nghề | 0.8897 [SOURCE_3] giao trinh Luat lao dong CB 2005 (1) | tr.95 | - Có quan hệ nhân quả giữa hành vi vi phạm và thiệt hại tài | 0.5862 [SOURCE_4] luu-ban-nhap-tu-dong-3-4 | tr.41 | Mục 2. TRÁCH NHIỆM VẬT CHẤT > Điều 129. Bồi thường thiệt hại | 0.411 | R15: gemini-3.5-flash-lite | S15: 15 | T15: 1 | U15: 0.92 | V15: Yes | W15: Yes | X15: PASS | Z15: PASS | AA15: =IF(Z15="",X15,Z15) | AC15: [AI] Đồng ý với chấm tự động
A16: LAW_A_015 | B16: Scenario-based | C16: Một NLĐ gây thiệt hại tài sản cho NSDLĐ khi thực hiện nghĩa vụ lao động. Theo cách phân loại của giáo trình, đây thuộc nhóm quan hệ nào? | D16: Thuộc quan hệ về bồi thường thiệt hại liên quan đến quan hệ lao động. | E16: Căn cứ: phần “Bài 1 - Bồi thường thiệt hại”, trang 5. Nội dung được tài liệu xác nhận: Thuộc quan hệ về bồi thường thiệt hại liên quan đến quan hệ lao động. | F16: 5 | G16: Bài 1 - Bồi thường thiệt hại | H16: bồi thường thiệt hại | tài sản | I16: Hard | J16: Single Chunk | K16: Yes | L16: Answer from document | N16: giao trinh Luat lao dong CB 2005 (1) | O16: Theo tài liệu được cung cấp, khi một chủ thể gây thiệt hại về tài sản cho bên kia khi thực hiện quyền và nghĩa vụ lao động, giữa họ sẽ phát sinh quan hệ về bồi thường thiệt hại [SOURCE_2]. Các quan hệ pháp luật về bồi thường thiệt hại này được chia thành ba loại, trong đó bao gồm: - Quan hệ bồi thường thiệt hại tài sản [SOURCE_1]. | P16: [SOURCE_1] giao trinh Luat lao dong CB 2005 (1) | tr.5 | (2) Quan hệ học nghề | 0.9491 [SOURCE_2] giao trinh Luat lao dong CB 2005 (1) | tr.5 | (2) Quan hệ học nghề | 0.8208 | Q16: [SOURCE_1] giao trinh Luat lao dong CB 2005 (1) | tr.5 | (2) Quan hệ học nghề | 0.9491 [SOURCE_2] giao trinh Luat lao dong CB 2005 (1) | tr.5 | (2) Quan hệ học nghề | 0.8208 [SOURCE_3] giao trinh Luat lao dong CB 2005 (1) | tr.95 | - Có quan hệ nhân quả giữa hành vi vi phạm và thiệt hại tài | 0.6305 [SOURCE_4] ILO-VCCI_Labour-Law-Guide-Book-V04-Final | tr.10 | CHƯƠNG I. QUAN HỆ LAO ĐỘNG VÀ HỢP ĐỒNG LAO ĐỘNG > I. QUAN HỆ | 0.5306 [SOURCE_5] giao trinh Luat lao dong CB 2005 (1) | tr.95 | IV. TRÁCH NHIỆM VẬT CHẤT TRONG QUAN HỆ LAO ĐỘNG > 1. Khái ni | 0.422 | R16: gemini-3.5-flash-lite | S16: 20.8 | T16: 1 | U16: 0.84615385 | V16: Yes | W16: Yes | X16: PASS | Z16: PASS | AA16: =IF(Z16="",X16,Z16) | AC16: [AI] Ngắn nhưng đúng nhóm quan hệ bồi thường thiệt hại
A17: LAW_A_016 | B17: Scenario-based | C17: Một người tìm việc thông qua trung tâm dịch vụ việc làm. Theo giáo trình, quan hệ này có nằm trong đối tượng điều chỉnh của Luật lao động không? | D17: Có. Đây là một dạng quan hệ về việc làm giữa NLĐ và trung tâm dịch vụ việc làm, được xếp vào các quan hệ liên quan đến quan hệ lao động. | E17: Căn cứ: phần “Bài 1 - Quan hệ việc làm”, trang 5. Nội dung được tài liệu xác nhận: Có. Đây là một dạng quan hệ về việc làm giữa NLĐ và trung tâm dịch vụ việc làm, được xếp vào các quan hệ liên quan đến quan hệ lao động. | F17: 5 | G17: Bài 1 - Quan hệ việc làm | H17: NLĐ | trung tâm dịch vụ việc làm | quan hệ việc làm | I17: Hard | J17: Single Chunk | K17: Yes | L17: Answer from document | N17: giao trinh Luat lao dong CB 2005 (1) | O17: Dựa trên tài liệu được cung cấp, đối tượng điều chỉnh của Luật lao động bao gồm hai nhóm quan hệ xã hội: quan hệ lao động và các quan hệ liên quan đến quan hệ lao động (phát sinh trong quá trình sử dụng lao động) [SOURCE_1]. Trong đó, tài liệu nêu rõ "Các quan hệ liên quan đến quan hệ lao động" là những quan hệ phát sinh từ hoặc có liên quan chặt chẽ với quan hệ lao động [SOURCE_1]. Tuy nhiên, trong các đoạn văn bản được cung cấp, không có thông tin chi tiết cụ thể xác định việc "một người tìm việc thông qua trung tâm dịch vụ việc làm" có trực tiếp thuộc đối tượng điều chỉnh của Luật lao động hay không, mặc dù người lao động có quyền "trực tiếp liên hệ với người sử dụng lao động hoặc thông qua tổ chức dịch vụ việc làm để tìm việc làm" theo Điều 10 [SOURCE_3]. Do đó, dựa trên tài liệu được cung cấp, tôi không tìm thấy thông tin đầy đủ để khẳng định chắc chắn rằng quan hệ tìm việc thông qua trung tâm dịch vụ việc làm này có nằm trong đối tượng điều chỉnh của Luật lao động hay không. | P17: [SOURCE_1] giao trinh Luat lao dong CB 2005 (1) | tr.3 | BÀI 1 > KHÁI NIỆM LUẬT LAO ĐỘNG VIỆT NAM > I - ĐỐI TƯỢNG VÀ | 0.9622 [SOURCE_3] luu-ban-nhap-tu-dong-3-4 | tr.73 | Điều 10. Quyền làm việc của người lao động | 0.5572 | Q17: [SOURCE_1] giao trinh Luat lao dong CB 2005 (1) | tr.3 | BÀI 1 > KHÁI NIỆM LUẬT LAO ĐỘNG VIỆT NAM > I - ĐỐI TƯỢNG VÀ | 0.9622 [SOURCE_2] giao trinh Luat lao dong CB 2005 (1) | tr.3 | a - Quan hệ lao động | 0.6522 [SOURCE_3] luu-ban-nhap-tu-dong-3-4 | tr.73 | Điều 10. Quyền làm việc của người lao động | 0.5572 | R17: gemini-3.5-flash-lite | S17: 19.8 | T17: 1 | U17: 0.80769231 | V17: Yes | W17: No | X17: PASS | Y17: Không trích đúng trang 5 (±1) | Z17: PARTIAL | AA17: =IF(Z17="",X17,Z17) | AC17: [AI] PASS oan của scorer: không kết luận 'Có', nói không đủ thông tin dù giáo trình xếp quan hệ với trung tâm dịch vụ việc làm vào quan hệ việc làm
A18: LAW_A_017 | B18: Multi-hop | C18: Từ cách giáo trình xác định đối tượng và phương pháp điều chỉnh, hãy giải thích vì sao HĐLĐ vừa mang tính thỏa thuận vừa chịu giới hạn pháp luật. | D18: Các bên tự do, bình đẳng, tự nguyện thỏa thuận về quá trình lao động, nhưng pháp luật đặt ra khung/chuẩn mực, trong đó quyền lợi thường được ấn định mức tối thiểu và nghĩa vụ ở mức tối đa để bảo vệ quan hệ lao động. | E18: Căn cứ: phần “Bài 1 - Đối tượng & phương pháp”, trang 4. Nội dung được tài liệu xác nhận: Các bên tự do, bình đẳng, tự nguyện thỏa thuận về quá trình lao động, nhưng pháp luật đặt ra khung/chuẩn mực, trong đó quyền lợi thường được ấn định mức tối thiểu và nghĩa vụ ở mức tối đa để bảo vệ quan hệ lao động. | F18: 4 | G18: Bài 1 - Đối tượng & phương pháp | H18: tự do thỏa thuận | khung pháp lý | quyền tối thiểu | nghĩa vụ tối đa | I18: Hard | J18: Multiple Chunks | K18: Yes | L18: Answer from document | N18: giao trinh Luat lao dong CB 2005 (1) | O18: Dựa trên tài liệu được cung cấp, phương pháp thỏa thuận trong Luật lao động cho phép các bên cùng nhau thỏa thuận các vấn đề liên quan trong quá trình lao động trên cơ sở tự nguyện, bình đẳng nhằm đảm bảo cùng có lợi và tạo điều kiện thực hiện tốt nghĩa vụ [SOURCE_1]. Các chủ thể thực hiện quyền tự định đoạt của mình thông qua sự tự do, thương lượng và thỏa thuận [SOURCE_1]. Tuy nhiên, phương pháp thỏa thuận trong Luật lao động chịu sự giới hạn và có sự khác biệt so với Luật dân sự: - Trong Luật lao động, các chủ thể tham gia quan hệ lao động không bình đẳng về địa vị và không độc lập với nhau về tổ chức [SOURCE_1]. - Do đó, để điều hòa mối quan hệ này và bảo vệ người lao động, Nhà nước thông qua pháp luật đã đặt ra những quy định nhằm nâng cao vị trí của người lao động để họ bình đẳng hơn với người sử dụng lao động [SOURCE_1]. - Vì vậy, mặc dù là tự do thỏa thuận và các chủ thể thực hiện quyền tự định đoạt, sự thỏa thuận đó luôn phải nằm trong khuôn khổ pháp luật và quan hệ lao động luôn mang yếu tố quản lý [SOURCE_1]. | P18: [SOURCE_1] giao trinh Luat lao dong CB 2005 (1) | tr.7 | a - Phương pháp thỏa thuận | 0.5369 | Q18: [SOURCE_1] giao trinh Luat lao dong CB 2005 (1) | tr.7 | a - Phương pháp thỏa thuận | 0.5369 [SOURCE_2] giao trinh Luat lao dong CB 2005 (1) | tr.7 | 2 - Phương pháp điều chỉnh của luật lao động | 0.4546 [SOURCE_3] giao trinh Luat lao dong CB 2005 (1) | tr.182 | 5. Đặc điểm và phân loại thẩm quyền của công đoàn > a. Đặc đ | 0.4193 | R18: gemini-3.5-flash-lite | S18: 16.4 | T18: 0.25 | U18: 0.69230769 | V18: Yes | W18: No | X18: PARTIAL | Y18: Thiếu từ khóa (25%); Không trích đúng trang 4 (±1) | Z18: PASS | AA18: =IF(Z18="",X18,Z18) | AC18: [AI] Không chắc: đủ ý thỏa thuận + Nhà nước đặt khung bảo vệ NLĐ; thiếu câu chữ 'quyền tối thiểu, nghĩa vụ tối đa'
A19: LAW_A_018 | B19: Multi-hop | C19: Giáo trình liên hệ quan hệ tranh chấp lao động và đình công với mục tiêu ổn định quan hệ lao động như thế nào? | D19: Việc giải quyết tranh chấp/đình công do các cơ quan, tổ chức có thẩm quyền thực hiện nhằm bảo đảm quyền lợi các bên và duy trì sự hài hòa, ổn định của quan hệ lao động. | E19: Căn cứ: phần “Bài 1 - Tranh chấp lao động”, trang 7. Nội dung được tài liệu xác nhận: Việc giải quyết tranh chấp/đình công do các cơ quan, tổ chức có thẩm quyền thực hiện nhằm bảo đảm quyền lợi các bên và duy trì sự hài hòa, ổn định của quan hệ lao động. | F19: 7 | G19: Bài 1 - Tranh chấp lao động | H19: tranh chấp | đình công | cơ quan thẩm quyền | hài hòa | ổn định | I19: Hard | J19: Single Chunk | K19: Yes | L19: Answer from document | N19: giao trinh Luat lao dong CB 2005 (1) | O19: Dựa trên tài liệu được cung cấp, việc giải quyết các tranh chấp lao động và các cuộc đình công do các tổ chức, cơ quan có thẩm quyền thực hiện (như Hội đồng hòa giải ở cơ sở, Hội đồng trọng tài lao động cấp tỉnh hoặc Tòa án nhân dân) nhằm mục đích bảo đảm quyền lợi cho cả hai bên và đảm bảo sự hài hòa, ổn định của quan hệ lao động [SOURCE_1]. Vì vậy, quan hệ về giải quyết các tranh chấp lao động và các cuộc đình công thuộc đối tượng điều chỉnh của Luật lao động [SOURCE_1]. | P19: [SOURCE_1] giao trinh Luat lao dong CB 2005 (1) | tr.6 | (6) Quan hệ về giải quyết các tranh chấp lao động và các cuộ | 0.9696 | Q19: [SOURCE_1] giao trinh Luat lao dong CB 2005 (1) | tr.6 | (6) Quan hệ về giải quyết các tranh chấp lao động và các cuộ | 0.9696 [SOURCE_2] giao trinh Luat lao dong CB 2005 (1) | tr.13 | Giáo trình Luật Lao động cơ bản | 0.7965 [SOURCE_3] luu-ban-nhap-tu-dong-3-4 | tr.60 | Mục 5. ĐÌNH CÔNG Điều 198. Đình công | 0.6755 [SOURCE_4] luu-ban-nhap-tu-dong-3-4 | tr.133 | Mục 4 ĐÌNH CÔNG VÀ GIẢI QUYẾT ĐÌNH CÔNG > Điều 209. Đình côn | 0.5837 | R19: gemini-3.5-flash-lite | S19: 20.4 | T19: 1 | U19: 0.93939394 | V19: Yes | W19: Yes | X19: PASS | Z19: PASS | AA19: =IF(Z19="",X19,Z19) | AC19: [AI] Đồng ý với chấm tự động
A20: LAW_A_019 | B20: Source-awareness | C20: Nếu hỏi “quy định hiện hành năm 2026 về làm thêm giờ”, RAG có nên chỉ dùng con số trong giáo trình 2005 không? | D20: Không nên. Giáo trình là nguồn lịch sử/giảng dạy cũ; hệ thống phải nhận diện thời điểm của nguồn và không trình bày quy định trong tài liệu này như pháp luật hiện hành năm 2026 nếu không có nguồn cập nhật. | E20: Căn cứ: phần “Lưu ý nguồn/tính thời điểm”, trang 1. Nội dung được tài liệu xác nhận: Không nên. Giáo trình là nguồn lịch sử/giảng dạy cũ; hệ thống phải nhận diện thời điểm của nguồn và không trình bày quy định trong tài liệu này như pháp luật hiện hành năm 2026 nếu không có nguồn cập nhật. | F20: 1 | G20: Lưu ý nguồn/tính thời điểm | H20: nguồn 2005 | lịch sử | không suy diễn hiện hành | I20: Hard | J20: Multiple Chunks | K20: Yes | L20: Answer with temporal caveat | M20: Tests temporal grounding. | N20: giao trinh Luat lao dong CB 2005 (1) | O20: Dựa trên tài liệu được cung cấp, tôi không tìm thấy thông tin để trả lời câu hỏi này. | R20: (no LLM call: early exit) | S20: 18.1 | T20: 0 | U20: 0 | V20: No | W20: No | X20: FAIL | Y20: Từ chối trả lời dù câu hỏi có đáp án | Z20: FAIL | AA20: =IF(Z20="",X20,Z20) | AB20: DEF-04 | AC20: [AI] Từ chối; câu hỏi về hành vi RAG, cần SME xem lại thiết kế test
A21: LAW_A_020 | B21: Synthesis | C21: Theo giáo trình, vì sao Luật lao động không chỉ điều chỉnh việc “đi làm nhận lương” mà còn bao phủ nhiều quan hệ khác? | D21: Vì ngoài quan hệ lao động làm công ăn lương, quá trình sử dụng lao động còn phát sinh các quan hệ gắn chặt như việc làm, học nghề, bồi thường, BHXH, công đoàn, tranh chấp/đình công và quản lý lao động; các quan hệ này cần được điều chỉnh để quan hệ lao động vận hành ổn định. | E21: Căn cứ: phần “Bài 1 - Tổng hợp” Nội dung được tài liệu xác nhận: Vì ngoài quan hệ lao động làm công ăn lương, quá trình sử dụng lao động còn phát sinh các quan hệ gắn chặt như việc làm, học nghề, bồi thường, BHXH, công đoàn, tranh chấp/đình công và quản lý lao động; các quan hệ này cần được điều chỉnh để quan hệ lao động vận hành ổn định. | G21: Bài 1 - Tổng hợp | H21: quan hệ lao động | quan hệ liên quan | ổn định | I21: Hard | J21: Multiple Chunks | K21: Yes | L21: Answer from document | N21: giao trinh Luat lao dong CB 2005 (1) | O21: Theo giáo trình, Luật lao động không chỉ điều chỉnh quan hệ lao động làm công ăn lương mà còn bao phủ nhiều quan hệ khác vì đối tượng điều chỉnh của Luật lao động bao gồm hai nhóm quan hệ xã hội: nhóm quan hệ lao động và nhóm các quan hệ liên quan đến quan hệ lao động (phát sinh trong quá trình sử dụng lao động) [SOURCE_5]. Bên cạnh quan hệ lao động làm công ăn lương là quan hệ chủ yếu, Luật lao động còn điều chỉnh một số quan hệ xã hội khác có liên quan chặt chẽ với quan hệ lao động, bao gồm [SOURCE_3]: - Quan hệ về việc làm [SOURCE_3]. - Quan hệ học nghề [SOURCE_3]. - Quan hệ về bồi thường thiệt hại [SOURCE_3]. - Quan hệ về bảo hiểm xã hội [SOURCE_3]. - Quan hệ giữa người sử dụng lao động với tổ chức Công đoàn, đại diện của tập thể người lao động [SOURCE_3]. - Quan hệ về giải quyết các tranh chấp lao động và các cuộc đình công [SOURCE_3]. - Quan hệ về quản lý lao động [SOURCE_3]. Ngoài ra, bản thân quan hệ lao động vừa mang tính kinh tế vừa mang tính xã hội [SOURCE_4]. Luật lao động không chỉ giải quyết các mục tiêu kinh tế như lợi nhuận, tiền lương và sự tăng trưởng trong sản xuất kinh doanh, mà còn phải giải quyết các vấn đề xã hội như việc làm, công bằng, dân chủ, tương trợ cộng đồng ngay trong quá trình lao động và tại các doanh nghiệp để làm động lực phát triển kinh tế [SOURCE_4]. | P21: [SOURCE_3] giao trinh Luat lao dong CB 2005 (1) | tr.4 | b - Các quan hệ liên quan đến quan hệ lao động | 0.8773 [SOURCE_4] giao trinh Luat lao dong CB 2005 (1) | tr.13 | Giáo trình Luật Lao động cơ bản | 0.8155 [SOURCE_5] giao trinh Luat lao dong CB 2005 (1) | tr.3 | BÀI 1 > KHÁI NIỆM LUẬT LAO ĐỘNG VIỆT NAM > I - ĐỐI TƯỢNG VÀ | 0.7594 | Q21: [SOURCE_1] giao trinh Luat lao dong CB 2005 (1) | tr.3 | a - Quan hệ lao động | 0.9642 [SOURCE_2] giao trinh Luat lao dong CB 2005 (1) | tr.3 | a - Quan hệ lao động | 0.9122 [SOURCE_3] giao trinh Luat lao dong CB 2005 (1) | tr.4 | b - Các quan hệ liên quan đến quan hệ lao động | 0.8773 [SOURCE_4] giao trinh Luat lao dong CB 2005 (1) | tr.13 | Giáo trình Luật Lao động cơ bản | 0.8155 [SOURCE_5] giao trinh Luat lao dong CB 2005 (1) | tr.3 | BÀI 1 > KHÁI NIỆM LUẬT LAO ĐỘNG VIỆT NAM > I - ĐỐI TƯỢNG VÀ | 0.7594 | R21: gemini-3.5-flash-lite | S21: 19.1 | T21: 0.66666667 | U21: 0.89285714 | V21: Yes | W21: n/a | X21: PARTIAL | Y21: Thiếu từ khóa (67%) | Z21: PASS | AA21: =IF(Z21="",X21,Z21) | AC21: [AI] Đủ 7 quan hệ liên quan; scorer chấm thiếu từ khóa oan
A22: LAW_B_001 | B22: Direct Fact | C22: Theo sổ tay, hợp đồng lao động có thể được giao kết bằng lời nói trong trường hợp nào? | D22: Theo tài liệu, giao kết bằng lời nói áp dụng với công việc tạm thời có thời hạn dưới 03 tháng. | E22: Căn cứ: phần “Phần I - Hợp đồng lao động”, trang 11. Nội dung được tài liệu xác nhận: Theo tài liệu, giao kết bằng lời nói áp dụng với công việc tạm thời có thời hạn dưới 03 tháng. | F22: 11 | G22: Phần I - Hợp đồng lao động | H22: lời nói | tạm thời | dưới 03 tháng | I22: Easy | J22: Single Chunk | K22: Yes | L22: Answer from document | N22: so-tay-kien-thuc-phap-luat-lao-dong-cdi | O22: Theo tài liệu được cung cấp, việc giao kết hợp đồng lao động bằng lời nói chỉ được áp dụng trong trường hợp làm công việc tạm thời có thời hạn dưới 03 tháng [SOURCE_1], [SOURCE_2]. | P22: [SOURCE_1] so-tay-kien-thuc-phap-luat-lao-dong-cdi | tr.11 | Trả lời: | 0.9907 [SOURCE_2] so-tay-kien-thuc-phap-luat-lao-dong-cdi | tr.49 | Trả lời: | 0.9852 | Q22: [SOURCE_1] so-tay-kien-thuc-phap-luat-lao-dong-cdi | tr.11 | Trả lời: | 0.9907 [SOURCE_2] so-tay-kien-thuc-phap-luat-lao-dong-cdi | tr.49 | Trả lời: | 0.9852 [SOURCE_3] Văn-bản-hợp-nhất-18-VBHN-VPQH | tr.7 | Điều 14. Hình thức hợp đồng lao động | 0.9647 [SOURCE_4] giao trinh Luat lao dong CB 2005 (1) | tr.36 | b. Hình thức của hợp đồng lao động | 0.9553 [SOURCE_5] so-tay-kien-thuc-phap-luat-lao-dong-cdi | tr.6 | Mục lục > KIẾN THỨC VỀ PHÁP LUẬT LAO ĐỘNG | 0.7975 | R22: gemini-3.5-flash-lite | S22: 16 | T22: 1 | U22: 1 | V22: Yes | W22: Yes | X22: PASS | Z22: PASS | AA22: =IF(Z22="",X22,Z22) | AC22: [AI] Đồng ý với chấm tự động
A23: LAW_B_002 | B23: Concept | C23: Vì sao sổ tay khuyến nghị nên ký hợp đồng lao động? | D23: Vì hợp đồng thể hiện thỏa thuận về công việc, lương, điều kiện làm việc, quyền và nghĩa vụ và là căn cứ xem xét khi phát sinh tranh chấp. | E23: Căn cứ: phần “Phần I - Hợp đồng lao động” Nội dung được tài liệu xác nhận: Vì hợp đồng thể hiện thỏa thuận về công việc, lương, điều kiện làm việc, quyền và nghĩa vụ và là căn cứ xem xét khi phát sinh tranh chấp. | G23: Phần I - Hợp đồng lao động | H23: thỏa thuận | căn cứ | tranh chấp | I23: Easy | J23: Single Chunk | K23: Yes | L23: Answer from document | N23: so-tay-kien-thuc-phap-luat-lao-dong-cdi | O23: Dựa trên tài liệu được cung cấp, sổ tay khuyến nghị việc ký kết hợp đồng lao động vì những lý do sau: * **Đối với người lao động:** Nhằm đảm bảo quyền lợi của họ, đồng thời là căn cứ để hạn chế việc người sử dụng lao động bóc lột, đánh đập hoặc vi phạm quyền lợi của người lao động [SOURCE_1]. * **Đối với người sử dụng lao động:** Hợp đồng lao động là căn cứ để quản lý người lao động và chỉ rõ nghĩa vụ của người lao động đối với người sử dụng lao động [SOURCE_1]. * **Đối với cả hai bên:** Việc thực hiện tốt các nguyên tắc của hợp đồng giúp các bên đảm bảo được quyền và nghĩa vụ của mình, từ đó tránh xảy ra tranh chấp, kiện tụng ảnh hưởng đến việc làm của cả hai bên [SOURCE_1]. | P23: [SOURCE_1] so-tay-kien-thuc-phap-luat-lao-dong-cdi | tr.12 | Trả lời: | 0.466 | Q23: [SOURCE_1] so-tay-kien-thuc-phap-luat-lao-dong-cdi | tr.12 | Trả lời: | 0.466 | R23: gemini-3.5-flash-lite | S23: 22.8 | T23: 0.66666667 | U23: 0.6 | V23: Yes | W23: n/a | X23: PARTIAL | Y23: Thiếu từ khóa (67%) | Z23: PARTIAL | AA23: =IF(Z23="",X23,Z23) | AC23: [AI] Đúng tài liệu (sổ tay tr.12) nhưng thiếu ý 'căn cứ xem xét khi tranh chấp'
A24: LAW_B_003 | B24: Direct Fact | C24: Sổ tay có đề cập nội dung “khi nào được ký HĐLĐ không xác định thời hạn” ở phần nào? | D24: Nội dung này nằm trong Phần I - Hợp đồng lao động. | E24: Căn cứ: phần “Phần I - Hợp đồng lao động”, trang 6. Nội dung được tài liệu xác nhận: Nội dung này nằm trong Phần I - Hợp đồng lao động. | F24: 6 | G24: Phần I - Hợp đồng lao động | H24: HĐLĐ không xác định thời hạn | I24: Easy | J24: Single Chunk | K24: Yes | L24: Answer from document | N24: so-tay-kien-thuc-phap-luat-lao-dong-cdi | O24: Dựa trên tài liệu được cung cấp, nội dung liên quan đến việc khi nào hợp đồng lao động trở thành hoặc phải ký kết hợp đồng lao động không xác định thời hạn được đề cập tại các phần sau: * **Phần (b) của Mục "5. Gia hạn HĐLĐ":** Khi hợp đồng lao động xác định thời hạn đầu tiên kết thúc, người sử dụng lao động chỉ có thể ký thêm một hợp đồng lao động xác định thời hạn nữa và sau đó phải ký hợp đồng lao động không xác định thời hạn với người lao động [SOURCE_1]. * **Phần "Điều 20. Loại hợp đồng lao động":** Kể từ ngày hợp đồng lao động hết hạn mà hai bên không ký kết hợp đồng lao động mới thì hợp đồng đã giao kết theo điểm b khoản này trở thành hợp đồng lao động không xác định thời hạn; hoặc trường hợp hai bên ký kết hợp đồng lao động mới là hợp đồng lao động xác định thời hạn thì cũng chỉ được ký thêm 01 lần, sau đó nếu người lao động vẫn tiếp tục làm việc thì phải ký kết hợp đồng lao động không xác định thời hạn (trừ một số trường hợp ngoại lệ pháp luật quy định) [SOURCE_3]. * **Phần "Trả lời:":** Có hai trường hợp chuyển từ xác định thời hạn sang không xác định thời hạn: (1) Hết hạn hợp đồng xác định thời hạn sau 30 ngày mà hai bên không ký hợp đồng lao động mới thì hợp đồng đã giao kết trở thành hợp đồng lao động không xác định thời hạn; hoặc (2) Trường hợp hai bên ký kết hợp đồng lao động mới là hợp đồng xác định thời hạn thì cũng chỉ được ký thêm 01 lần, sau đó nếu người lao động vẫn tiếp tục làm việc thì phải ký kết hợp đồng lao động không xác định thời hạn [SOURCE_4]. * **Phần "Điều 22. Loại hợp đồng lao động":** Khi hợp đồng lao động quy định tại điểm b và điểm c khoản 1 Điều này hết hạn mà người lao động vẫn tiếp tục làm việc thì trong thời hạn 30 ngày, kể từ ngày hợp đồng lao động hết hạn, hai bên phải ký kết hợp đồng lao động mới; nếu không ký kết thì hợp đồng theo điểm b trở thành hợp đồng không xác định thời hạn. Đồng thời, trường hợp hai bên ký kết hợp đồng lao động mới là hợp đồng xác định thời hạn thì cũng chỉ được ký thêm 01 lần, sau đó nếu người lao động vẫn tiếp tục làm việc thì phải ký kết hợp đồng lao động không xác định thời hạn [SOURCE_5]. | P24: [SOURCE_1] ILO-VCCI_Labour-Law-Guide-Book-V04-Final | tr.18 | 5. Gia hạn HĐLĐ | 0.8821 [SOURCE_3] Văn-bản-hợp-nhất-18-VBHN-VPQH | tr.9 | Điều 20. Loại hợp đồng lao động | 0.8088 [SOURCE_4] so-tay-kien-thuc-phap-luat-lao-dong-cdi | tr.13 | Trả lời: | 0.8098 [SOURCE_5] luu-ban-nhap-tu-dong-3-4 | tr.76 | Điều 22. Loại hợp đồng lao động | 0.7937 | Q24: [SOURCE_1] ILO-VCCI_Labour-Law-Guide-Book-V04-Final | tr.18 | 5. Gia hạn HĐLĐ | 0.8821 [SOURCE_2] ILO-VCCI_Labour-Law-Guide-Book-V04-Final | tr.19 | (a) Đối với người lao động cao tuổi: | 0.8691 [SOURCE_3] Văn-bản-hợp-nhất-18-VBHN-VPQH | tr.9 | Điều 20. Loại hợp đồng lao động | 0.8088 [SOURCE_4] so-tay-kien-thuc-phap-luat-lao-dong-cdi | tr.13 | Trả lời: | 0.8098 [SOURCE_5] luu-ban-nhap-tu-dong-3-4 | tr.76 | Điều 22. Loại hợp đồng lao động | 0.7937 | R24: gemini-3.5-flash-lite | S24: 18 | T24: 1 | U24: 0.875 | V24: Yes | W24: No | X24: PASS | Y24: Không trích đúng trang 6 (±1) | Z24: FAIL | AA24: =IF(Z24="",X24,Z24) | AB24: DEF-02 | AC24: [AI] PASS oan của scorer: không nêu 'Phần I - Hợp đồng lao động', trả lời bằng mục của cẩm nang ILO và Điều 20
